Workbook

Sheet Calculations
J1: Day 0 | R1: Day 1 | Z1: Day 2 | AJ1: Day 4 | AP1: Day 6 | AX1: Day 9 | BF1: Day 12 | BN1: Day 14 | BV1: Day 19 | CD1: Day 26 | CL1: Day 30 | CT1: Day 36 | DB1: Day 44 | DJ1: Day 51 | DR1: Day 58 | DZ1: Day 65 | EH1: Day 74 | EP1: Day 83 | EX1: Day 92 | FF1: Day 96
A2: Sample ID | B2: Jar volume (mL) | C2: volume of soil | D2: rate constant R (L atm/K mol) | E2: Incubation temp (K) | F2: vol headspace (L) | G2: GWC | H2: mass wet soil in jar (g) | I2: mass dry soil in jar (g) | J2: flush end | K2: Time sampled | L2: incubation time elapsed (day) | M2: Average temperature (K) | N2: CO2 concentration (ppm) | O2: CH4 concentration (ppm) | P2: C-CO2 rate (ug C-CO2/g dry soil/h) | Q2: C-CO2 amount (ug C-CO2/g dry soil) For cumulative! | R2: flush end | S2: Time sampled | T2: incubation time elapsed (day) | U2: Average temperature (K) | V2: CO2 concentration (ppm) | W2: CH4 concentration (ppm) | X2: C-CO2 rate (ug C-CO2/g dry soil/h) | Y2: C-CO2 amount (ug C-CO2/g dry soil) For cumulative! | Z2: flush end | AA2: Time sampled | AB2: incubation time elapsed (day) | AC2: Average temperature (K) | AD2: CO2 concentration (ppm) | AE2: CH4 concentration (ppm) | AF2: C-CO2 rate (ug C-CO2/g dry soil/h) | AG2: C-CO2 amount (ug C-CO2/g dry soil) For cumulative! | AH2: flush end | AI2: Time sampled | AJ2: incubation time elapsed (day) | AK2: Average temperature (K) | AL2: CO2 concentration (ppm) | AM2: CH4 concentration (ppm) | AN2: C-CO2 rate (ug C-CO2/g dry soil/h) | AO2: C-CO2 amount (ug C-CO2/g dry soil) For cumulative! | AP2: flush end | AQ2: Time sampled | AR2: incubation time elapsed (day) | AS2: Average temperature (K) | AT2: CO2 concentration (ppm) | AU2: CH4 concentration (ppm) | AV2: C-CO2 rate (ug C-CO2/g dry soil/h) | AW2: C-CO2 amount (ug C-CO2/g dry soil) For cumulative! | AX2: flush end | AY2: Time sampled | AZ2: incubation time elapsed (day) | BA2: Average temperature (K) | BB2: CO2 concentration (ppm) | BC2: CH4 concentration (ppm) | BD2: C-CO2 rate (ug C-CO2/g dry soil/h) | BE2: C-CO2 amount (ug C-CO2/g dry soil) For cumulative! | BF2: flush end | BG2: Time sampled | BH2: incubation time elapsed (day) | BI2: Average temperature (K) | BJ2: CO2 concentration (ppm) | BK2: CH4 concentration (ppm) | BL2: C-CO2 rate (ug C-CO2/g dry soil/h) | BM2: C-CO2 amount (ug C-CO2/g dry soil) For cumulative! | BN2: flush end | BO2: Time sampled | BP2: incubation time elapsed (day) | BQ2: Average temperature (K) | BR2: CO2 concentration (ppm) | BS2: CH4 concentration (ppm) | BT2: C-CO2 rate (ug C-CO2/g dry soil/h) | BU2: C-CO2 amount (ug C-CO2/g dry soil) For cumulative! | BV2: flush end | BW2: Time sampled | BX2: incubation time elapsed (day) | BY2: Average temperature (K) | BZ2: CO2 concentration (ppm) | CA2: CH4 concentration (ppm) | CB2: C-CO2 rate (ug C-CO2/g dry soil/h) | CC2: C-CO2 amount (ug C-CO2/g dry soil) For cumulative! | CD2: flush end | CE2: Time sampled | CF2: incubation time elapsed (day) | CG2: Average temperature (K) | CH2: CO2 concentration (ppm) | CI2: CH4 concentration (ppm) | CJ2: C-CO2 rate (ug C-CO2/g dry soil/h) | CK2: C-CO2 amount (ug C-CO2/g dry soil) For cumulative! | CL2: flush end | CM2: Time sampled | CN2: incubation time elapsed (day) | CO2: Average temperature (K) | CP2: CO2 concentration (ppm) | CQ2: CH4 concentration (ppm) | CR2: C-CO2 rate (ug C-CO2/g dry soil/h) | CS2: C-CO2 amount (ug C-CO2/g dry soil) For cumulative! | CT2: flush end | CU2: Time sampled | CV2: incubation time elapsed (day) | CW2: Average temperature (K) | CX2: CO2 concentration (ppm) | CY2: CH4 concentration (ppm) | CZ2: C-CO2 rate (ug C-CO2/g dry soil/h) | DA2: C-CO2 amount (ug C-CO2/g dry soil) For cumulative! | DB2: flush end | DC2: Time sampled | DD2: incubation time elapsed (day) | DE2: Average temperature (K) | DF2: CO2 concentration (ppm) | DG2: CH4 concentration (ppm) | DH2: C-CO2 rate (ug C-CO2/g dry soil/h) | DI2: C-CO2 amount (ug C-CO2/g dry soil) For cumulative! | DJ2: flush end | DK2: Time sampled | DL2: incubation time elapsed (day) | DM2: Average temperature (K) | DN2: CO2 concentration (ppm) | DO2: CH4 concentration (ppm) | DP2: C-CO2 rate (ug C-CO2/g dry soil/h) | DQ2: C-CO2 amount (ug C-CO2/g dry soil) For cumulative! | DR2: flush end | DS2: Time sampled | DT2: incubation time elapsed (day) | DU2: Average temperature (K) | DV2: CO2 concentration (ppm) | DW2: CH4 concentration (ppm) | DX2: C-CO2 rate (ug C-CO2/g dry soil/h) | DY2: C-CO2 amount (ug C-CO2/g dry soil) For cumulative! | DZ2: flush end | EA2: Time sampled | EB2: incubation time elapsed (day) | EC2: Average temperature (K) | ED2: CO2 concentration (ppm) | EE2: CH4 concentration (ppm) | EF2: C-CO2 rate (ug C-CO2/g dry soil/h) | EG2: C-CO2 amount (ug C-CO2/g dry soil) For cumulative! | EH2: flush end | EI2: Time sampled | EJ2: incubation time elapsed (day) | EK2: Average temperature (K) | EL2: CO2 concentration (ppm) | EM2: CH4 concentration (ppm) | EN2: C-CO2 rate (ug C-CO2/g dry soil/h) | EO2: C-CO2 amount (ug C-CO2/g dry soil) For cumulative! | EP2: flush end | EQ2: Time sampled | ER2: incubation time elapsed (day) | ES2: Average temperature (K) | ET2: CO2 concentration (ppm) | EU2: CH4 concentration (ppm) | EV2: C-CO2 rate (ug C-CO2/g dry soil/h) | EW2: C-CO2 amount (ug C-CO2/g dry soil) For cumulative! | EX2: flush end | EY2: Time sampled | EZ2: incubation time elapsed (day) | FA2: Average temperature (K) | FB2: CO2 concentration (ppm) | FC2: CH4 concentration (ppm) | FD2: C-CO2 rate (ug C-CO2/g dry soil/h) | FE2: C-CO2 amount (ug C-CO2/g dry soil) For cumulative! | FF2: flush end | FG2: Time sampled | FH2: incubation time elapsed (day) | FI2: Average temperature (K) | FJ2: CO2 concentration (ppm) | FK2: CH4 concentration (ppm) | FL2: C-CO2 rate (ug C-CO2/g dry soil/h) | FM2: C-CO2 amount (ug C-CO2/g dry soil) For cumulative!
A3: AT 3 REP 5 H2 | B3: 473.176 | C3: =Vol_soil_calc!L2 -> 24.308555 | D3: 0.082057366 | E3: 275.15 | F3: =(B3-C3)/1000 -> 0.44886744 | G3: =[1]incubation_physical_chemical!$I$2 -> 0.542 | H3: 40.046 | I3: =H3/(G3+1) -> 25.970169 | J3: 44447.816 | K3: 44447.825 | L3: =(K3-J3) -> 0.0090277778 | M3: 275.15 | N3: 88.638 | O3: 0.045 | P3: =N3*($F3)*(1/$D3)*(1/$M3)*(1/$I3)*(12)*(1/(L3*24)) -> 3.7580741 | Q3: =N3*($F3)*(1/$D3)*(1/$M3)*(1/$I3)*(12) -> 0.81424939 | S3: 0.63541667 | T3: =(S3-R3) -> 0.63541667 | U3: 275.15 | V3: 1212.562 | W3: 0.802 | X3: =V3*($F3)*(1/$D3)*(1/$U3)*(1/$I3)*(12)*(1/(T3*24)) -> 0.73041823 | Y3: =V3*($F3)*(1/$D3)*(1/$U3)*(1/$I3)*(12) -> 11.138878 | Z3: 44448.699 | AA3: 44449.544 | AB3: =(AA3-Z3) -> 0.84583333 | AC3: 278.97625 | AD3: 726.256 | AE3: 0.398 | AF3: =AD3*($F3)*(1/$D3)*(1/$AC3)*(1/$I3)*(12)*(1/(AB3*24)) -> 0.32414063 | AG3: =AD3*($F3)*(1/$D3)*(1/$AC3)*(1/$I3)*(12) -> 6.5800548 | AH3: 44449.625 | AI3: 44451.69 | AJ3: =(AI3-AH3) -> 2.0645833 | AK3: 275.30392 | AL3: 336.558 | AM3: 0.055 | AN3: =AL3*($F3)*(1/$D3)*(1/$AK3)*(1/$I3)*(12)*(1/(AJ3*24)) -> 0.062360686 | AO3: =AL3*($F3)*(1/$D3)*(1/$AK3)*(1/$I3)*(12) -> 3.089972 | AP3: 44451.785 | AQ3: 44453.597 | AR3: =(AQ3-AP3) -> 1.8111111 | AS3: 275.34575 | AT3: 265.748 | AU3: 0.02 | AV3: =AT3*($F3)*(1/$D3)*(1/$AS3)*(1/$I3)*(12)*(1/(AR3*24)) -> 0.056123184 | AW3: =AT3*($F3)*(1/$D3)*(1/$AS3)*(1/$I3)*(12) -> 2.4394877 | AX3: 44453.792 | AY3: 44456.554 | AZ3: =(AY3-AX3) -> 2.7618056 | BA3: 275.28258 | BB3: 388.544 | BC3: 0.045 | BD3: =BB3*($F3)*(1/$D3)*(1/$BA3)*(1/$I3)*(12)*(1/(AZ3*24)) -> 0.053822534 | BE3: =BB3*($F3)*(1/$D3)*(1/$BA3)*(1/$I3)*(12) -> 3.567537 | BF3: 44456.599 | BG3: 44459.628 | BH3: =(BG3-BF3) -> 3.0291667 | BI3: 274.02612 | BJ3: 188.541 | BK3: 0.06 | BL3: =BJ3*($F3)*(1/$D3)*(1/$BI3)*(1/$I3)*(12)*(1/(BH3*24)) -> 0.023921391 | BM3: =BJ3*($F3)*(1/$D3)*(1/$BI3)*(1/$I3)*(12) -> 1.7390852 | BN3: 44459.66 | BO3: 44461.475 | BP3: =(BO3-BN3) -> 1.8152778 | BQ3: 276.14042 | BR3: 263.023 | BS3: 0.029 | BT3: =BR3*($F3)*(1/$D3)*(1/$BQ3)*(1/$I3)*(12)*(1/(BP3*24)) -> 0.055260706 | BU3: =BR3*($F3)*(1/$D3)*(1/$BQ3)*(1/$I3)*(12) -> 2.4075248 | BV3: 44461.515 | BW3: 44466.524 | BX3: =(BW3-BV3) -> 5.0097222 | BY3: 276.28675 | BZ3: 603.036 | CA3: 0.046 | CB3: =BZ3*($F3)*(1/$D3)*(1/$BY3)*(1/$I3)*(12)*(1/(BX3*24)) -> 0.045884426 | CC3: =BZ3*($F3)*(1/$D3)*(1/$BY3)*(1/$I3)*(12) -> 5.5168375 | CD3: 44466.567 | CE3: 44473.499 | CF3: =(CE3-CD3) -> 6.9319444 | CG3: 276.30758 | CH3: 1982.822 | CI3: 0.038 | CJ3: =CH3*($F3)*(1/$D3)*(1/$CG3)*(1/$I3)*(12)*(1/(CF3*24)) -> 0.10902639 | CK3: =CH3*($F3)*(1/$D3)*(1/$CG3)*(1/$I3)*(12) -> 18.138357 | CL3: 44473.559 | CM3: 44477.575 | CN3: =(CM3-CL3) -> 4.0159722 | CO3: 276.45387 | CP3: 2754.93 | CQ3: 0.044 | CR3: =CP3*($F3)*(1/$D3)*(1/$CO3)*(1/$I3)*(12)*(1/(CN3*24)) -> 0.26133222 | CS3: =CP3*($F3)*(1/$D3)*(1/$CO3)*(1/$I3)*(12) -> 25.18807 | CT3: 44477.635 | CU3: 44483.503 | CV3: =(CU3-CT3) -> 5.86875 | CW3: 277.06033 | CX3: 2207.193 | CY3: 0.023 | CZ3: =CX3*($F3)*(1/$D3)*(1/$CW3)*(1/$I3)*(12)*(1/(CV3*24)) -> 0.14296052 | DA3: =CX3*($F3)*(1/$D3)*(1/$CW3)*(1/$I3)*(12) -> 20.135989 | DB3: 44483.569 | DC3: 44491.541 | DD3: =(DC3-DB3) -> 7.9715278 | DE3: 277.2485 | DF3: 2277.725 | DG3: 0.077 | DH3: =DF3*($F3)*(1/$D3)*(1/$DE3)*(1/$I3)*(12)*(1/(DD3*24)) -> 0.10853912 | DI3: =DF3*($F3)*(1/$D3)*(1/$DE3)*(1/$I3)*(12) -> 20.765342 | DJ3: 44491.59 | DK3: 44498.61 | DL3: =(DK3-DJ3) -> 7.0201389 | DM3: 276.97687 | DN3: 1161.868 | DO3: 0.031 | DP3: =DN3*($F3)*(1/$D3)*(1/$DM3)*(1/$I3)*(12)*(1/(DL3*24)) -> 0.062930813 | DQ3: =DN3*($F3)*(1/$D3)*(1/$DM3)*(1/$I3)*(12) -> 10.602793 | DR3: 44498.637 | DS3: 44505.545 | DT3: =(DS3-DR3) -> 6.9076389 | DU3: 276.60067 | DV3: 791.542 | DW3: 0.022 | DX3: =DV3*($F3)*(1/$D3)*(1/$DU3)*(1/$I3)*(12)*(1/(DT3*24)) -> 0.043630168 | DY3: =DV3*($F3)*(1/$D3)*(1/$DU3)*(1/$I3)*(12) -> 7.2331547 | DZ3: 44505.58 | EA3: 44512.586 | EB3: =(EA3-DZ3) -> 7.00625 | EC3: 277.08092 | ED3: 676.274 | EE3: 0.021 | EF3: =ED3*($F3)*(1/$D3)*(1/$EC3)*(1/$I3)*(12)*(1/(EB3*24)) -> 0.036688184 | EG3: =ED3*($F3)*(1/$D3)*(1/$EC3)*(1/$I3)*(12) -> 6.1691181 | EH3: 44512.626 | EI3: 44521.664 | EJ3: =(EI3-EH3) -> 9.0381944 | EK3: 276.87229 | EL3: 923.145 | EM3: 0.043 | EN3: =EL3*($F3)*(1/$D3)*(1/$EK3)*(1/$I3)*(12)*(1/(EJ3*24)) -> 0.038851207 | EO3: =EL3*($F3)*(1/$D3)*(1/$EK3)*(1/$I3)*(12) -> 8.4274743 | EP3: 44521.722 | EQ3: 44530.573 | ER3: =(EQ3-EP3) -> 8.8506944 | ES3: 276.6425 | ET3: 795.353 | EU3: 0.034 | EV3: =ET3*($F3)*(1/$D3)*(1/$ES3)*(1/$I3)*(12)*(1/(ER3*24)) -> 0.034210502 | EW3: =ET3*($F3)*(1/$D3)*(1/$ES3)*(1/$I3)*(12) -> 7.2668808 | EX3: 44530.612 | EY3: 44539.614 | EZ3: =(EY3-EX3) -> 9.0020833 | FA3: 276.01467 | FB3: 697.36 | FC3: 0.029 | FD3: =FB3*($F3)*(1/$D3)*(1/$FA3)*(1/$I3)*(12)*(1/(EZ3*24)) -> 0.029558175 | FE3: =FB3*($F3)*(1/$D3)*(1/$FA3)*(1/$I3)*(12) -> 6.3860437 | FF3: 44539.627 | FG3: 44543.532 | FH3: =(FG3-FF3) -> 3.9048611 | FI3: 276.789 | FJ3: 469.044 | FK3: 0.021 | FL3: =FJ3*($F3)*(1/$D3)*(1/$FI3)*(1/$I3)*(12)*(1/(FH3*24)) -> 0.045704076 | FM3: =FJ3*($F3)*(1/$D3)*(1/$FI3)*(1/$I3)*(12) -> 4.2832337
A4: AT 3 REP 6 H2 | B4: 473.176 | C4: =Vol_soil_calc!L3 -> 26.629721 | D4: 0.082057366 | E4: 275.15 | F4: =(B4-C4)/1000 -> 0.44654628 | G4: =[1]incubation_physical_chemical!$I$3 -> 0.934 | H4: 38.781 | I4: =H4/(G4+1) -> 20.052223 | J4: 44447.816 | K4: 44447.831 | L4: =(K4-J4) -> 0.015277778 | M4: 275.15 | N4: 126.593 | O4: 0.073 | P4: =N4*($F4)*(1/$D4)*(1/$M4)*(1/$I4)*(12)*(1/(L4*24)) -> 4.0863575 | Q4: =N4*($F4)*(1/$D4)*(1/$M4)*(1/$I4)*(12) -> 1.4983311 | S4: 0.64027778 | T4: =(S4-R4) -> 0.64027778 | U4: 275.15 | V4: 1456.476 | W4: 1.332 | X4: =V4*($F4)*(1/$D4)*(1/$U4)*(1/$I4)*(12)*(1/(T4*24)) -> 1.1218163 | Y4: =V4*($F4)*(1/$D4)*(1/$U4)*(1/$I4)*(12) -> 17.238578 | Z4: 44448.699 | AA4: 44449.55 | AB4: =(AA4-Z4) -> 0.85138889 | AC4: 278.97625 | AD4: 726.617 | AE4: 0.604 | AF4: =AD4*($F4)*(1/$D4)*(1/$AC4)*(1/$I4)*(12)*(1/(AB4*24)) -> 0.41511337 | AG4: =AD4*($F4)*(1/$D4)*(1/$AC4)*(1/$I4)*(12) -> 8.4821498 | AH4: 44449.633 | AI4: 44451.685 | AJ4: =(AI4-AH4) -> 2.0520833 | AK4: 275.30392 | AL4: 438.302 | AM4: 0.049 | AN4: =AL4*($F4)*(1/$D4)*(1/$AK4)*(1/$I4)*(12)*(1/(AJ4*24)) -> 0.10527432 | AO4: =AL4*($F4)*(1/$D4)*(1/$AK4)*(1/$I4)*(12) -> 5.1847602 | AP4: 44451.785 | AQ4: 44453.6 | AR4: =(AQ4-AP4) -> 1.8145833 | AS4: 275.34575 | AT4: 354.849 | AU4: 0.07 | AV4: =AT4*($F4)*(1/$D4)*(1/$AS4)*(1/$I4)*(12)*(1/(AR4*24)) -> 0.096370622 | AW4: =AT4*($F4)*(1/$D4)*(1/$AS4)*(1/$I4)*(12) -> 4.1969406 | AX4: 44453.792 | AY4: 44456.57 | AZ4: =(AY4-AX4) -> 2.7777778 | BA4: 275.28258 | BB4: 339.729 | BC4: 0.023 | BD4: =BB4*($F4)*(1/$D4)*(1/$BA4)*(1/$I4)*(12)*(1/(AZ4*24)) -> 0.060285485 | BE4: =BB4*($F4)*(1/$D4)*(1/$BA4)*(1/$I4)*(12) -> 4.0190323 | BF4: 44456.599 | BG4: 44459.623 | BH4: =(BG4-BF4) -> 3.0236111 | BI4: 274.02612 | BJ4: 183.245 | BK4: 0.019 | BL4: =BJ4*($F4)*(1/$D4)*(1/$BI4)*(1/$I4)*(12)*(1/(BH4*24)) -> 0.030010318 | BM4: =BJ4*($F4)*(1/$D4)*(1/$BI4)*(1/$I4)*(12) -> 2.1777488 | BN4: 44459.66 | BO4: 44461.469 | BP4: =(BO4-BN4) -> 1.8090278 | BQ4: 276.14042 | BR4: 249.103 | BS4: 0.044 | BT4: =BR4*($F4)*(1/$D4)*(1/$BQ4)*(1/$I4)*(12)*(1/(BP4*24)) -> 0.067664382 | BU4: =BR4*($F4)*(1/$D4)*(1/$BQ4)*(1/$I4)*(12) -> 2.9377619 | BV4: 44461.515 | BW4: 44466.528 | BX4: =(BW4-BV4) -> 5.0138889 | BY4: 276.28675 | BZ4: 441.349 | CA4: 0.031 | CB4: =BZ4*($F4)*(1/$D4)*(1/$BY4)*(1/$I4)*(12)*(1/(BX4*24)) -> 0.043231844 | CC4: =BZ4*($F4)*(1/$D4)*(1/$BY4)*(1/$I4)*(12) -> 5.2022318 | CD4: 44466.567 | CE4: 44473.503 | CF4: =(CE4-CD4) -> 6.9361111 | CG4: 276.30758 | CH4: 1908.836 | CI4: 0.054 | CJ4: =CH4*($F4)*(1/$D4)*(1/$CG4)*(1/$I4)*(12)*(1/(CF4*24)) -> 0.13515003 | CK4: =CH4*($F4)*(1/$D4)*(1/$CG4)*(1/$I4)*(12) -> 22.497975 | CL4: 44473.559 | CM4: 44477.579 | CN4: =(CM4-CL4) -> 4.0201389 | CO4: 276.45387 | CP4: 2111.644 | CQ4: 0.019 | CR4: =CP4*($F4)*(1/$D4)*(1/$CO4)*(1/$I4)*(12)*(1/(CN4*24)) -> 0.25781806 | CS4: =CP4*($F4)*(1/$D4)*(1/$CO4)*(1/$I4)*(12) -> 24.875146 | CT4: 44477.635 | CU4: 44483.508 | CV4: =(CU4-CT4) -> 5.8729167 | CW4: 277.06033 | CX4: 2031.396 | CY4: 0.046 | CZ4: =CX4*($F4)*(1/$D4)*(1/$CW4)*(1/$I4)*(12)*(1/(CV4*24)) -> 0.16940365 | DA4: =CX4*($F4)*(1/$D4)*(1/$CW4)*(1/$I4)*(12) -> 23.877445 | DB4: 44483.569 | DC4: 44491.557 | DD4: =(DC4-DB4) -> 7.9875 | DE4: 277.2485 | DF4: 1437.923 | DG4: 0.022 | DH4: =DF4*($F4)*(1/$D4)*(1/$DE4)*(1/$I4)*(12)*(1/(DD4*24)) -> 0.088107307 | DI4: =DF4*($F4)*(1/$D4)*(1/$DE4)*(1/$I4)*(12) -> 16.890171 | DJ4: 44491.59 | DK4: 44498.606 | DL4: =(DK4-DJ4) -> 7.0166667 | DM4: 276.97687 | DN4: 1011.602 | DO4: 0.028 | DP4: =DN4*($F4)*(1/$D4)*(1/$DM4)*(1/$I4)*(12)*(1/(DL4*24)) -> 0.070630405 | DQ4: =DN4*($F4)*(1/$D4)*(1/$DM4)*(1/$I4)*(12) -> 11.89416 | DR4: 44498.637 | DS4: 44505.54 | DT4: =(DS4-DR4) -> 6.9027778 | DU4: 276.60067 | DV4: 831.938 | DW4: 0.02 | DX4: =DV4*($F4)*(1/$D4)*(1/$DU4)*(1/$I4)*(12)*(1/(DT4*24)) -> 0.059124873 | DY4: =DV4*($F4)*(1/$D4)*(1/$DU4)*(1/$I4)*(12) -> 9.7950206 | DZ4: 44505.58 | EA4: 44512.582 | EB4: =(EA4-DZ4) -> 7.0020833 | EC4: 277.08092 | ED4: 863.082 | EE4: 0.044 | EF4: =ED4*($F4)*(1/$D4)*(1/$EC4)*(1/$I4)*(12)*(1/(EB4*24)) -> 0.060363518 | EG4: =ED4*($F4)*(1/$D4)*(1/$EC4)*(1/$I4)*(12) -> 10.144089 | EH4: 44512.626 | EI4: 44521.66 | EJ4: =(EI4-EH4) -> 9.0347222 | EK4: 276.87229 | EL4: 762.915 | EM4: 0.028 | EN4: =EL4*($F4)*(1/$D4)*(1/$EK4)*(1/$I4)*(12)*(1/(EJ4*24)) -> 0.041384549 | EO4: =EL4*($F4)*(1/$D4)*(1/$EK4)*(1/$I4)*(12) -> 8.9735497 | EP4: 44521.722 | EQ4: 44530.565 | ER4: =(EQ4-EP4) -> 8.8423611 | ES4: 276.6425 | ET4: 837.408 | EU4: 0.413 | EV4: =ET4*($F4)*(1/$D4)*(1/$ES4)*(1/$I4)*(12)*(1/(ER4*24)) -> 0.046452205 | EW4: =ET4*($F4)*(1/$D4)*(1/$ES4)*(1/$I4)*(12) -> 9.857932 | EX4: 44530.612 | EY4: 44539.595 | EZ4: =(EY4-EX4) -> 8.9833333 | FA4: 276.01467 | FB4: 840.694 | FC4: 0.069 | FD4: =FB4*($F4)*(1/$D4)*(1/$FA4)*(1/$I4)*(12)*(1/(EZ4*24)) -> 0.046007077 | FE4: =FB4*($F4)*(1/$D4)*(1/$FA4)*(1/$I4)*(12) -> 9.9191259 | FF4: 44539.627 | FG4: 44543.509 | FH4: =(FG4-FF4) -> 3.8819444 | FI4: 276.789 | FJ4: 460.26 | FK4: 0.09 | FL4: =FJ4*($F4)*(1/$D4)*(1/$FI4)*(1/$I4)*(12)*(1/(FH4*24)) -> 0.058124799 | FM4: =FJ4*($F4)*(1/$D4)*(1/$FI4)*(1/$I4)*(12) -> 5.4152938
A5: AT 3 REP 7 H2 | B5: 473.176 | C5: =Vol_soil_calc!L4 -> 22.66666 | D5: 0.082057366 | E5: 275.15 | F5: =(B5-C5)/1000 -> 0.45050934 | G5: =[1]incubation_physical_chemical!$I$4 -> 0.814 | H5: 34.037 | I5: =H5/(G5+1) -> 18.763506 | J5: 44447.816 | K5: 44447.84 | L5: =(K5-J5) -> 0.023611111 | M5: 275.15 | N5: 157.213 | O5: 0.055 | P5: =N5*($F5)*(1/$D5)*(1/$M5)*(1/$I5)*(12)*(1/(L5*24)) -> 3.5403382 | Q5: =N5*($F5)*(1/$D5)*(1/$M5)*(1/$I5)*(12) -> 2.0061917 | S5: 0.64444444 | T5: =(S5-R5) -> 0.64444444 | U5: 275.15 | V5: 1335.774 | W5: 0.824 | X5: =V5*($F5)*(1/$D5)*(1/$U5)*(1/$I5)*(12)*(1/(T5*24)) -> 1.102098 | Y5: =V5*($F5)*(1/$D5)*(1/$U5)*(1/$I5)*(12) -> 17.045783 | Z5: 44448.699 | AA5: 44449.554 | AB5: =(AA5-Z5) -> 0.85555556 | AC5: 278.97625 | AD5: 638.452 | AE5: 0.223 | AF5: =AD5*($F5)*(1/$D5)*(1/$AC5)*(1/$I5)*(12)*(1/(AB5*24)) -> 0.39134072 | AG5: =AD5*($F5)*(1/$D5)*(1/$AC5)*(1/$I5)*(12) -> 8.0355295 | AH5: 44449.625 | AI5: 44451.681 | AJ5: =(AI5-AH5) -> 2.05625 | AK5: 275.30392 | AL5: 493.493 | AM5: 0.179 | AN5: =AL5*($F5)*(1/$D5)*(1/$AK5)*(1/$I5)*(12)*(1/(AJ5*24)) -> 0.12753663 | AO5: =AL5*($F5)*(1/$D5)*(1/$AK5)*(1/$I5)*(12) -> 6.2939326 | AP5: 44451.778 | AQ5: 44453.606 | AR5: =(AQ5-AP5) -> 1.8284722 | AS5: 275.34575 | AT5: 315.212 | AU5: 0.04 | AV5: =AT5*($F5)*(1/$D5)*(1/$AS5)*(1/$I5)*(12)*(1/(AR5*24)) -> 0.091596365 | AW5: =AT5*($F5)*(1/$D5)*(1/$AS5)*(1/$I5)*(12) -> 4.0195538 | AX5: 44453.792 | AY5: 44456.567 | AZ5: =(AY5-AX5) -> 2.7743056 | BA5: 275.28258 | BB5: 452.546 | BC5: 0.058 | BD5: =BB5*($F5)*(1/$D5)*(1/$BA5)*(1/$I5)*(12)*(1/(AZ5*24)) -> 0.086690587 | BE5: =BB5*($F5)*(1/$D5)*(1/$BA5)*(1/$I5)*(12) -> 5.7721482 | BF5: 44456.599 | BG5: 44459.617 | BH5: =(BG5-BF5) -> 3.0180556 | BI5: 274.02612 | BJ5: 220.401 | BK5: 0.041 | BL5: =BJ5*($F5)*(1/$D5)*(1/$BI5)*(1/$I5)*(12)*(1/(BH5*24)) -> 0.038988507 | BM5: =BJ5*($F5)*(1/$D5)*(1/$BI5)*(1/$I5)*(12) -> 2.8240675 | BN5: 44459.66 | BO5: 44461.492 | BP5: =(BO5-BN5) -> 1.8326389 | BQ5: 276.14042 | BR5: 272.437 | BS5: 0.017 | BT5: =BR5*($F5)*(1/$D5)*(1/$BQ5)*(1/$I5)*(12)*(1/(BP5*24)) -> 0.078759229 | BU5: =BR5*($F5)*(1/$D5)*(1/$BQ5)*(1/$I5)*(12) -> 3.4640934 | BV5: 44461.515 | BW5: 44466.531 | BX5: =(BW5-BV5) -> 5.0166667 | BY5: 276.28675 | BZ5: 547.273 | CA5: 0.02 | CB5: =BZ5*($F5)*(1/$D5)*(1/$BY5)*(1/$I5)*(12)*(1/(BX5*24)) -> 0.057765822 | CC5: =BZ5*($F5)*(1/$D5)*(1/$BY5)*(1/$I5)*(12) -> 6.955005 | CD5: 44466.567 | CE5: 44473.506 | CF5: =(CE5-CD5) -> 6.9395833 | CG5: 276.30758 | CH5: 2107.249 | CI5: 0.037 | CJ5: =CH5*($F5)*(1/$D5)*(1/$CG5)*(1/$I5)*(12)*(1/(CF5*24)) -> 0.16077995 | CK5: =CH5*($F5)*(1/$D5)*(1/$CG5)*(1/$I5)*(12) -> 26.777901 | CL5: 44473.559 | CM5: 44477.584 | CN5: =(CM5-CL5) -> 4.025 | CO5: 276.45387 | CP5: 1857.636 | CQ5: 0.018 | CR5: =CP5*($F5)*(1/$D5)*(1/$CO5)*(1/$I5)*(12)*(1/(CN5*24)) -> 0.24423859 | CS5: =CP5*($F5)*(1/$D5)*(1/$CO5)*(1/$I5)*(12) -> 23.593448 | CT5: 44477.635 | CU5: 44483.526 | CV5: =(CU5-CT5) -> 5.8909722 | CW5: 277.06033 | CX5: 1449.447 | CY5: 0.019 | CZ5: =CX5*($F5)*(1/$D5)*(1/$CW5)*(1/$I5)*(12)*(1/(CV5*24)) -> 0.12992217 | DA5: =CX5*($F5)*(1/$D5)*(1/$CW5)*(1/$I5)*(12) -> 18.368829 | DB5: 44483.569 | DC5: 44491.553 | DD5: =(DC5-DB5) -> 7.9833333 | DE5: 277.2485 | DF5: 1242.024 | DG5: 0.026 | DH5: =DF5*($F5)*(1/$D5)*(1/$DE5)*(1/$I5)*(12)*(1/(DD5*24)) -> 0.082095388 | DI5: =DF5*($F5)*(1/$D5)*(1/$DE5)*(1/$I5)*(12) -> 15.729476 | DJ5: 44491.59 | DK5: 44498.603 | DL5: =(DK5-DJ5) -> 7.0131944 | DM5: 276.97687 | DN5: 858.673 | DO5: 0.056 | DP5: =DN5*($F5)*(1/$D5)*(1/$DM5)*(1/$I5)*(12)*(1/(DL5*24)) -> 0.064671161 | DQ5: =DN5*($F5)*(1/$D5)*(1/$DM5)*(1/$I5)*(12) -> 10.885234 | DR5: 44498.637 | DS5: 44505.537 | DT5: =(DS5-DR5) -> 6.8993056 | DU5: 276.60067 | DV5: 715.858 | DW5: 0.022 | DX5: =DV5*($F5)*(1/$D5)*(1/$DU5)*(1/$I5)*(12)*(1/(DT5*24)) -> 0.054879547 | DY5: =DV5*($F5)*(1/$D5)*(1/$DU5)*(1/$I5)*(12) -> 9.0871384 | DZ5: 44505.58 | EA5: 44512.598 | EB5: =(EA5-DZ5) -> 7.0180556 | EC5: 277.08092 | ED5: 629.431 | EE5: 0.02 | EF5: =ED5*($F5)*(1/$D5)*(1/$EC5)*(1/$I5)*(12)*(1/(EB5*24)) -> 0.047355121 | EG5: =ED5*($F5)*(1/$D5)*(1/$EC5)*(1/$I5)*(12) -> 7.9761809 | EH5: 44512.626 | EI5: 44521.647 | EJ5: =(EI5-EH5) -> 9.0215278 | EK5: 276.87229 | EL5: 759.278 | EM5: 0.044 | EN5: =EL5*($F5)*(1/$D5)*(1/$EK5)*(1/$I5)*(12)*(1/(EJ5*24)) -> 0.044471673 | EO5: =EL5*($F5)*(1/$D5)*(1/$EK5)*(1/$I5)*(12) -> 9.6288584 | EP5: 44521.722 | EQ5: 44530.58 | ER5: =(EQ5-EP5) -> 8.8576389 | ES5: 276.6425 | ET5: 812.082 | EU5: 0.027 | EV5: =ET5*($F5)*(1/$D5)*(1/$ES5)*(1/$I5)*(12)*(1/(ER5*24)) -> 0.04848476 | EW5: =ET5*($F5)*(1/$D5)*(1/$ES5)*(1/$I5)*(12) -> 10.307052 | EX5: 44530.612 | EY5: 44539.565 | EZ5: =(EY5-EX5) -> 8.9534722 | FA5: 276.01467 | FB5: 1517.855 | FC5: 0.175 | FD5: =FB5*($F5)*(1/$D5)*(1/$FA5)*(1/$I5)*(12)*(1/(EZ5*24)) -> 0.089856371 | FE5: =FB5*($F5)*(1/$D5)*(1/$FA5)*(1/$I5)*(12) -> 19.308636 | FF5: 44539.627 | FG5: 44543.491 | FH5: =(FG5-FF5) -> 3.8638889 | FI5: 276.789 | FJ5: 498.413 | FK5: 0.019 | FL5: =FJ5*($F5)*(1/$D5)*(1/$FI5)*(1/$I5)*(12)*(1/(FH5*24)) -> 0.06818018 | FM5: =FJ5*($F5)*(1/$D5)*(1/$FI5)*(1/$I5)*(12) -> 6.3225754
A6: AT 3 REP 8 H2 | B6: 473.176 | C6: =Vol_soil_calc!L5 -> 19.855698 | D6: 0.082057366 | E6: 275.15 | F6: =(B6-C6)/1000 -> 0.4533203 | G6: {=[1]incubation_physical_chemical!$I$5:$I$25} -> 0.365 | H6: 35.708 | I6: =H6/(G6+1) -> 26.159707 | J6: 44447.816 | K6: 44447.845 | L6: =(K6-J6) -> 0.029166667 | M6: 275.15 | N6: 197.083 | O6: 0.079 | P6: =N6*($F6)*(1/$D6)*(1/$M6)*(1/$I6)*(12)*(1/(L6*24)) -> 2.5930899 | Q6: =N6*($F6)*(1/$D6)*(1/$M6)*(1/$I6)*(12) -> 1.8151629 | S6: 0.64861111 | T6: =(S6-R6) -> 0.64861111 | U6: 275.15 | V6: 869.095 | W6: 0.676 | X6: =V6*($F6)*(1/$D6)*(1/$U6)*(1/$I6)*(12)*(1/(T6*24)) -> 0.51420711 | Y6: =V6*($F6)*(1/$D6)*(1/$U6)*(1/$I6)*(12) -> 8.0044907 | Z6: 44448.699 | AA6: 44449.56 | AB6: =(AA6-Z6) -> 0.86111111 | AC6: 278.97625 | AD6: 540.49 | AE6: 0.281 | AF6: =AD6*($F6)*(1/$D6)*(1/$AC6)*(1/$I6)*(12)*(1/(AB6*24)) -> 0.23756692 | AG6: =AD6*($F6)*(1/$D6)*(1/$AC6)*(1/$I6)*(12) -> 4.9097163 | AH6: 44449.633 | AI6: 44451.676 | AJ6: =(AI6-AH6) -> 2.0423611 | AK6: 275.30392 | AL6: 307.109 | AM6: 0.179 | AN6: =AL6*($F6)*(1/$D6)*(1/$AK6)*(1/$I6)*(12)*(1/(AJ6*24)) -> 0.057672974 | AO6: =AL6*($F6)*(1/$D6)*(1/$AK6)*(1/$I6)*(12) -> 2.8269369 | AP6: 44451.778 | AQ6: 44453.61 | AR6: =(AQ6-AP6) -> 1.8326389 | AS6: 275.34575 | AT6: 236.031 | AU6: 0.1 | AV6: =AT6*($F6)*(1/$D6)*(1/$AS6)*(1/$I6)*(12)*(1/(AR6*24)) -> 0.04938994 | AW6: =AT6*($F6)*(1/$D6)*(1/$AS6)*(1/$I6)*(12) -> 2.1723342 | AX6: 44453.792 | AY6: 44456.562 | AZ6: =(AY6-AX6) -> 2.7701389 | BA6: 275.28258 | BB6: 248.84 | BC6: 0.096 | BD6: =BB6*($F6)*(1/$D6)*(1/$BA6)*(1/$I6)*(12)*(1/(AZ6*24)) -> 0.034455983 | BE6: =BB6*($F6)*(1/$D6)*(1/$BA6)*(1/$I6)*(12) -> 2.2907486 | BF6: 44456.599 | BG6: 44459.614 | BH6: =(BG6-BF6) -> 3.0145833 | BI6: 274.02612 | BJ6: 93.784 | BK6: 0.015 | BL6: =BJ6*($F6)*(1/$D6)*(1/$BI6)*(1/$I6)*(12)*(1/(BH6*24)) -> 0.011987654 | BM6: =BJ6*($F6)*(1/$D6)*(1/$BI6)*(1/$I6)*(12) -> 0.8673068 | BN6: 44459.66 | BO6: 44461.497 | BP6: =(BO6-BN6) -> 1.8375 | BQ6: 276.14042 | BR6: 186.863 | BS6: 0.019 | BT6: =BR6*($F6)*(1/$D6)*(1/$BQ6)*(1/$I6)*(12)*(1/(BP6*24)) -> 0.038885771 | BU6: =BR6*($F6)*(1/$D6)*(1/$BQ6)*(1/$I6)*(12) -> 1.7148625 | BV6: 44461.515 | BW6: 44466.536 | BX6: =(BW6-BV6) -> 5.0215278 | BY6: 276.28675 | BZ6: 429.262 | CA6: 0.035 | CB6: =BZ6*($F6)*(1/$D6)*(1/$BY6)*(1/$I6)*(12)*(1/(BX6*24)) -> 0.032670159 | CC6: =BZ6*($F6)*(1/$D6)*(1/$BY6)*(1/$I6)*(12) -> 3.9372986 | CD6: 44466.567 | CE6: 44473.511 | CF6: =(CE6-CD6) -> 6.9444444 | CG6: 276.30758 | CH6: 1670.02 | CI6: 0.042 | CJ6: =CH6*($F6)*(1/$D6)*(1/$CG6)*(1/$I6)*(12)*(1/(CF6*24)) -> 0.091900122 | CK6: =CH6*($F6)*(1/$D6)*(1/$CG6)*(1/$I6)*(12) -> 15.316687 | CL6: 44473.559 | CM6: 44477.602 | CN6: =(CM6-CL6) -> 4.0430556 | CO6: 276.45387 | CP6: 1474.182 | CQ6: 0.019 | CR6: =CP6*($F6)*(1/$D6)*(1/$CO6)*(1/$I6)*(12)*(1/(CN6*24)) -> 0.13926547 | CS6: =CP6*($F6)*(1/$D6)*(1/$CO6)*(1/$I6)*(12) -> 13.513392 | CT6: 44477.635 | CU6: 44483.53 | CV6: =(CU6-CT6) -> 5.8951389 | CW6: 277.06033 | CX6: 1369.524 | CY6: 0.023 | CZ6: =CX6*($F6)*(1/$D6)*(1/$CW6)*(1/$I6)*(12)*(1/(CV6*24)) -> 0.08853724 | DA6: =CX6*($F6)*(1/$D6)*(1/$CW6)*(1/$I6)*(12) -> 12.526544 | DB6: 44483.569 | DC6: 44491.549 | DD6: =(DC6-DB6) -> 7.9791667 | DE6: 277.2485 | DF6: 1286.815 | DG6: 0.029 | DH6: =DF6*($F6)*(1/$D6)*(1/$DE6)*(1/$I6)*(12)*(1/(DD6*24)) -> 0.061420606 | DI6: =DF6*($F6)*(1/$D6)*(1/$DE6)*(1/$I6)*(12) -> 11.762046 | DJ6: 44491.59 | DK6: 44498.597 | DL6: =(DK6-DJ6) -> 7.0076389 | DM6: 276.97687 | DN6: 1100.502 | DO6: 0.05 | DP6: =DN6*($F6)*(1/$D6)*(1/$DM6)*(1/$I6)*(12)*(1/(DL6*24)) -> 0.05986877 | DQ6: =DN6*($F6)*(1/$D6)*(1/$DM6)*(1/$I6)*(12) -> 10.068929 | DR6: 44498.637 | DS6: 44505.554 | DT6: =(DS6-DR6) -> 6.9166667 | DU6: 276.60067 | DV6: 643.069 | DW6: 0.099 | DX6: =DV6*($F6)*(1/$D6)*(1/$DU6)*(1/$I6)*(12)*(1/(DT6*24)) -> 0.035492144 | DY6: =DV6*($F6)*(1/$D6)*(1/$DU6)*(1/$I6)*(12) -> 5.8916959 | DZ6: 44505.58 | EA6: 44512.603 | EB6: =(EA6-DZ6) -> 7.0229167 | EC6: 277.08092 | ED6: 588.73 | EE6: 0.027 | EF6: =ED6*($F6)*(1/$D6)*(1/$EC6)*(1/$I6)*(12)*(1/(EB6*24)) -> 0.03194602 | EG6: =ED6*($F6)*(1/$D6)*(1/$EC6)*(1/$I6)*(12) -> 5.3845017 | EH6: 44512.626 | EI6: 44521.637 | EJ6: =(EI6-EH6) -> 9.0118056 | EK6: 276.87229 | EL6: 722.882 | EM6: 0.1 | EN6: =EL6*($F6)*(1/$D6)*(1/$EK6)*(1/$I6)*(12)*(1/(EJ6*24)) -> 0.030591504 | EO6: =EL6*($F6)*(1/$D6)*(1/$EK6)*(1/$I6)*(12) -> 6.6164325 | EP6: 44521.722 | EQ6: 44530.549 | ER6: =(EQ6-EP6) -> 8.8263889 | ES6: 276.6425 | ET6: 658.959 | EU6: 0.037 | EV6: =ET6*($F6)*(1/$D6)*(1/$ES6)*(1/$I6)*(12)*(1/(ER6*24)) -> 0.02849582 | EW6: =ET6*($F6)*(1/$D6)*(1/$ES6)*(1/$I6)*(12) -> 6.0363646 | EX6: 44530.612 | EY6: 44539.607 | EZ6: =(EY6-EX6) -> 8.9951389 | FA6: 276.01467 | FB6: 593.816 | FC6: 0.109 | FD6: =FB6*($F6)*(1/$D6)*(1/$FA6)*(1/$I6)*(12)*(1/(EZ6*24)) -> 0.025254373 | FE6: =FB6*($F6)*(1/$D6)*(1/$FA6)*(1/$I6)*(12) -> 5.4519982 | FF6: 44539.627 | FG6: 44543.525 | FH6: =(FG6-FF6) -> 3.8979167 | FI6: 276.789 | FJ6: 413.13 | FK6: 0.202 | FL6: =FJ6*($F6)*(1/$D6)*(1/$FI6)*(1/$I6)*(12)*(1/(FH6*24)) -> 0.040432452 | FM6: =FJ6*($F6)*(1/$D6)*(1/$FI6)*(1/$I6)*(12) -> 3.7824559
A7: AT 4 REP 5 H2 | B7: 473.176 | C7: =Vol_soil_calc!L6 -> 21.357253 | D7: 0.082057366 | E7: 275.15 | F7: =(B7-C7)/1000 -> 0.45181875 | G7: 0.441 | H7: 37.253 | I7: =H7/(G7+1) -> 25.852186 | J7: 44447.816 | K7: 44447.85 | L7: =(K7-J7) -> 0.034027778 | M7: 275.15 | N7: 147.908 | O7: 0.025 | P7: =N7*($F7)*(1/$D7)*(1/$M7)*(1/$I7)*(12)*(1/(L7*24)) -> 1.6823175 | Q7: =N7*($F7)*(1/$D7)*(1/$M7)*(1/$I7)*(12) -> 1.3738926 | S7: 0.65347222 | T7: =(S7-R7) -> 0.65347222 | U7: 275.15 | V7: 642.869 | W7: 0.518 | X7: =V7*($F7)*(1/$D7)*(1/$U7)*(1/$I7)*(12)*(1/(T7*24)) -> 0.38075467 | Y7: =V7*($F7)*(1/$D7)*(1/$U7)*(1/$I7)*(12) -> 5.9715025 | Z7: 44448.699 | AA7: 44449.565 | AB7: =(AA7-Z7) -> 0.86666667 | AC7: 278.97625 | AD7: 332.047 | AE7: 0.303 | AF7: =AD7*($F7)*(1/$D7)*(1/$AC7)*(1/$I7)*(12)*(1/(AB7*24)) -> 0.14625127 | AG7: =AD7*($F7)*(1/$D7)*(1/$AC7)*(1/$I7)*(12) -> 3.0420264 | AH7: 44449.625 | AI7: 44451.706 | AJ7: =(AI7-AH7) -> 2.0805556 | AK7: 275.30392 | AL7: 206.081 | AM7: 0.039 | AN7: =AL7*($F7)*(1/$D7)*(1/$AK7)*(1/$I7)*(12)*(1/(AJ7*24)) -> 0.03831472 | AO7: =AL7*($F7)*(1/$D7)*(1/$AK7)*(1/$I7)*(12) -> 1.9131817 | AP7: 44451.785 | AQ7: 44453.614 | AR7: =(AQ7-AP7) -> 1.8284722 | AS7: 275.34575 | AT7: 133.775 | AU7: 0.01 | AV7: =AT7*($F7)*(1/$D7)*(1/$AS7)*(1/$I7)*(12)*(1/(AR7*24)) -> 0.028296168 | AW7: =AT7*($F7)*(1/$D7)*(1/$AS7)*(1/$I7)*(12) -> 1.2417302 | AX7: 44453.792 | AY7: 44456.581 | AZ7: =(AY7-AX7) -> 2.7881944 | BA7: 275.28258 | BB7: 174.1 | BC7: 0.05 | BD7: =BB7*($F7)*(1/$D7)*(1/$BA7)*(1/$I7)*(12)*(1/(AZ7*24)) -> 0.02415552 | BE7: =BB7*($F7)*(1/$D7)*(1/$BA7)*(1/$I7)*(12) -> 1.6164069 | BF7: 44456.599 | BG7: 44459.646 | BH7: =(BG7-BF7) -> 3.0465278 | BI7: 274.02612 | BJ7: 103.486 | BK7: 0.034 | BL7: =BJ7*($F7)*(1/$D7)*(1/$BI7)*(1/$I7)*(12)*(1/(BH7*24)) -> 0.013200911 | BM7: =BJ7*($F7)*(1/$D7)*(1/$BI7)*(1/$I7)*(12) -> 0.96520659 | BN7: 44459.66 | BO7: 44461.458 | BP7: =(BO7-BN7) -> 1.7979167 | BQ7: 276.14042 | BR7: 117.095 | BS7: 0.021 | BT7: =BR7*($F7)*(1/$D7)*(1/$BQ7)*(1/$I7)*(12)*(1/(BP7*24)) -> 0.025116448 | BU7: =BR7*($F7)*(1/$D7)*(1/$BQ7)*(1/$I7)*(12) -> 1.0837747 | BV7: 44461.515 | BW7: 44466.501 | BX7: =(BW7-BV7) -> 4.9868056 | BY7: 276.28675 | BZ7: 401.722 | CA7: 0.055 | CB7: =BZ7*($F7)*(1/$D7)*(1/$BY7)*(1/$I7)*(12)*(1/(BX7*24)) -> 0.031050066 | CC7: =BZ7*($F7)*(1/$D7)*(1/$BY7)*(1/$I7)*(12) -> 3.7161754 | CD7: 44466.567 | CE7: 44473.515 | CF7: =(CE7-CD7) -> 6.9479167 | CG7: 276.30758 | CH7: 1223.426 | CI7: 0.033 | CJ7: =CH7*($F7)*(1/$D7)*(1/$CG7)*(1/$I7)*(12)*(1/(CF7*24)) -> 0.067865602 | CK7: =CH7*($F7)*(1/$D7)*(1/$CG7)*(1/$I7)*(12) -> 11.316589 | CL7: 44473.559 | CM7: 44477.607 | CN7: =(CM7-CL7) -> 4.0479167 | CO7: 276.45387 | CP7: 1165.385 | CQ7: 0.044 | CR7: =CP7*($F7)*(1/$D7)*(1/$CO7)*(1/$I7)*(12)*(1/(CN7*24)) -> 0.11090078 | CS7: =CP7*($F7)*(1/$D7)*(1/$CO7)*(1/$I7)*(12) -> 10.77401 | CT7: 44477.635 | CU7: 44483.548 | CV7: =(CU7-CT7) -> 5.9131944 | CW7: 277.06033 | CX7: 2037.531 | CY7: 0.024 | CZ7: =CX7*($F7)*(1/$D7)*(1/$CW7)*(1/$I7)*(12)*(1/(CV7*24)) -> 0.13244242 | DA7: =CX7*($F7)*(1/$D7)*(1/$CW7)*(1/$I7)*(12) -> 18.795787 | DB7: 44483.569 | DC7: 44491.575 | DD7: =(DC7-DB7) -> 8.0055556 | DE7: 277.2485 | DF7: 2653.738 | DG7: 0.055 | DH7: =DF7*($F7)*(1/$D7)*(1/$DE7)*(1/$I7)*(12)*(1/(DD7*24)) -> 0.1273259 | DI7: =DF7*($F7)*(1/$D7)*(1/$DE7)*(1/$I7)*(12) -> 24.46355 | DJ7: 44491.59 | DK7: 44498.626 | DL7: =(DK7-DJ7) -> 7.0368056 | DM7: 276.97687 | DN7: 1311.057 | DO7: 0.025 | DP7: =DN7*($F7)*(1/$D7)*(1/$DM7)*(1/$I7)*(12)*(1/(DL7*24)) -> 0.071634448 | DQ7: =DN7*($F7)*(1/$D7)*(1/$DM7)*(1/$I7)*(12) -> 12.097864 | DR7: 44498.637 | DS7: 44505.519 | DT7: =(DS7-DR7) -> 6.8819444 | DU7: 276.60067 | DV7: 1119.669 | DW7: 0.048 | DX7: =DV7*($F7)*(1/$D7)*(1/$DU7)*(1/$I7)*(12)*(1/(DT7*24)) -> 0.06263898 | DY7: =DV7*($F7)*(1/$D7)*(1/$DU7)*(1/$I7)*(12) -> 10.345872 | DZ7: 44505.58 | EA7: 44512.567 | EB7: =(EA7-DZ7) -> 6.9875 | EC7: 277.08092 | ED7: 632.444 | EE7: 0.024 | EF7: =ED7*($F7)*(1/$D7)*(1/$EC7)*(1/$I7)*(12)*(1/(EB7*24)) -> 0.034786685 | EG7: =ED7*($F7)*(1/$D7)*(1/$EC7)*(1/$I7)*(12) -> 5.8337271 | EH7: 44512.626 | EI7: 44521.645 | EJ7: =(EI7-EH7) -> 9.0194444 | EK7: 276.87229 | EL7: 741.349 | EM7: 0.041 | EN7: =EL7*($F7)*(1/$D7)*(1/$EK7)*(1/$I7)*(12)*(1/(EJ7*24)) -> 0.031614246 | EO7: =EL7*($F7)*(1/$D7)*(1/$EK7)*(1/$I7)*(12) -> 6.8434305 | EP7: 44521.722 | EQ7: 44530.576 | ER7: =(EQ7-EP7) -> 8.8541667 | ES7: 276.6425 | ET7: 735.508 | EU7: 0.045 | EV7: =ET7*($F7)*(1/$D7)*(1/$ES7)*(1/$I7)*(12)*(1/(ER7*24)) -> 0.031977184 | EW7: =ET7*($F7)*(1/$D7)*(1/$ES7)*(1/$I7)*(12) -> 6.7951516 | EX7: 44530.612 | EY7: 44539.617 | EZ7: =(EY7-EX7) -> 9.0055556 | FA7: 276.01467 | FB7: 819.533 | FC7: 0.027 | FD7: =FB7*($F7)*(1/$D7)*(1/$FA7)*(1/$I7)*(12)*(1/(EZ7*24)) -> 0.035110999 | FE7: =FB7*($F7)*(1/$D7)*(1/$FA7)*(1/$I7)*(12) -> 7.5886572 | FF7: 44539.627 | FG7: 44543.487 | FH7: =(FG7-FF7) -> 3.8597222 | FI7: 276.789 | FJ7: 429.025 | FK7: 0.025 | FL7: =FJ7*($F7)*(1/$D7)*(1/$FI7)*(1/$I7)*(12)*(1/(FH7*24)) -> 0.042765852 | FM7: =FJ7*($F7)*(1/$D7)*(1/$FI7)*(1/$I7)*(12) -> 3.9615434
A8: AT 4 REP 6 H2 | B8: 473.176 | C8: =Vol_soil_calc!L7 -> 17.917343 | D8: 0.082057366 | E8: 275.15 | F8: =(B8-C8)/1000 -> 0.45525866 | G8: 0.271 | H8: 34.708 | I8: =H8/(G8+1) -> 27.307632 | J8: 44447.816 | K8: 44447.855 | L8: =(K8-J8) -> 0.038888889 | M8: 275.15 | N8: 210.403 | O8: 0.124 | P8: =N8*($F8)*(1/$D8)*(1/$M8)*(1/$I8)*(12)*(1/(L8*24)) -> 1.9974848 | Q8: =N8*($F8)*(1/$D8)*(1/$M8)*(1/$I8)*(12) -> 1.8643191 | S8: 0.65763889 | T8: =(S8-R8) -> 0.65763889 | U8: 275.15 | V8: 786.806 | W8: 0.7 | X8: =V8*($F8)*(1/$D8)*(1/$U8)*(1/$I8)*(12)*(1/(T8*24)) -> 0.44171003 | Y8: =V8*($F8)*(1/$D8)*(1/$U8)*(1/$I8)*(12) -> 6.9716567 | Z8: 44448.699 | AA8: 44449.569 | AB8: =(AA8-Z8) -> 0.87013889 | AC8: 278.97625 | AD8: 479.487 | AE8: 0.777 | AF8: =AD8*($F8)*(1/$D8)*(1/$AC8)*(1/$I8)*(12)*(1/(AB8*24)) -> 0.20065391 | AG8: =AD8*($F8)*(1/$D8)*(1/$AC8)*(1/$I8)*(12) -> 4.1903225 | AH8: 9/10/2021 13:00:00 PM | AI8: 9/12/2021 16:51:00 PM | AJ8: =(AI9-AH9) -> 2.0729167 | AK8: 275.30392 | AL8: 283.27 | AM8: 0.275 | AN8: =AL8*($F8)*(1/$D8)*(1/$AK8)*(1/$I8)*(12)*(1/(AJ8*24)) -> 0.050423496 | AO8: =AL8*($F8)*(1/$D8)*(1/$AK8)*(1/$I8)*(12) -> 2.5085689 | AP8: 44451.778 | AQ8: 44453.619 | AR8: =(AQ8-AP8) -> 1.8409722 | AS8: 275.34575 | AT8: 231.029 | AU8: 0.01 | AV8: =AT8*($F8)*(1/$D8)*(1/$AS8)*(1/$I8)*(12)*(1/(AR8*24)) -> 0.046298561 | AW8: =AT8*($F8)*(1/$D8)*(1/$AS8)*(1/$I8)*(12) -> 2.0456247 | AX8: 44453.792 | AY8: 44456.588 | AZ8: =(AY8-AX8) -> 2.7958333 | BA8: 275.28258 | BB8: 190.296 | BC8: 0.203 | BD8: =BB8*($F8)*(1/$D8)*(1/$BA8)*(1/$I8)*(12)*(1/(AZ8*24)) -> 0.025116913 | BE8: =BB8*($F8)*(1/$D8)*(1/$BA8)*(1/$I8)*(12) -> 1.6853448 | BF8: 44456.599 | BG8: 44459.642 | BH8: =(BG8-BF8) -> 3.0423611 | BI8: 274.02612 | BJ8: 125.629 | BK8: 0.328 | BL8: =BJ8*($F8)*(1/$D8)*(1/$BI8)*(1/$I8)*(12)*(1/(BH8*24)) -> 0.015307835 | BM8: =BJ8*($F8)*(1/$D8)*(1/$BI8)*(1/$I8)*(12) -> 1.1177271 | BN8: 44459.66 | BO8: 44461.454 | BP8: =(BO8-BN8) -> 1.7944444 | BQ8: 276.14042 | BR8: 122.595 | BS8: 0.147 | BT8: =BR8*($F8)*(1/$D8)*(1/$BQ8)*(1/$I8)*(12)*(1/(BP8*24)) -> 0.025132713 | BU8: =BR8*($F8)*(1/$D8)*(1/$BQ8)*(1/$I8)*(12) -> 1.0823822 | BV8: 44461.515 | BW8: 44466.498 | BX8: =(BW8-BV8) -> 4.9833333 | BY8: 276.28675 | BZ8: 238.279 | CA8: 0.306 | CB8: =BZ8*($F8)*(1/$D8)*(1/$BY8)*(1/$I8)*(12)*(1/(BX8*24)) -> 0.017580547 | CC8: =BZ8*($F8)*(1/$D8)*(1/$BY8)*(1/$I8)*(12) -> 2.1026334 | CD8: 44466.567 | CE8: 44473.519 | CF8: =(CE8-CD8) -> 6.9527778 | CG8: 276.30758 | CH8: 621.904 | CI8: 0.397 | CJ8: =CH8*($F8)*(1/$D8)*(1/$CG8)*(1/$I8)*(12)*(1/(CF8*24)) -> 0.032885073 | CK8: =CH8*($F8)*(1/$D8)*(1/$CG8)*(1/$I8)*(12) -> 5.4874224 | CL8: 44473.559 | CM8: 44477.59 | CN8: =(CM8-CL8) -> 4.0305556 | CO8: 276.45387 | CP8: 894.687 | CQ8: 0.256 | CR8: =CP8*($F8)*(1/$D8)*(1/$CO8)*(1/$I8)*(12)*(1/(CN8*24)) -> 0.081566183 | CS8: =CP8*($F8)*(1/$D8)*(1/$CO8)*(1/$I8)*(12) -> 7.8901688 | CT8: 44477.635 | CU8: 44483.534 | CV8: =(CU8-CT8) -> 5.8993056 | CW8: 277.06033 | CX8: 1855.664 | CY8: 0.311 | CZ8: =CX8*($F8)*(1/$D8)*(1/$CW8)*(1/$I8)*(12)*(1/(CV8*24)) -> 0.11533223 | DA8: =CX8*($F8)*(1/$D8)*(1/$CW8)*(1/$I8)*(12) -> 16.329122 | DB8: 44483.569 | DC8: 44491.571 | DD8: =(DC8-DB8) -> 8.0013889 | DE8: 277.2485 | DF8: 2214.358 | DG8: 0.396 | DH8: =DF8*($F8)*(1/$D8)*(1/$DE8)*(1/$I8)*(12)*(1/(DD8*24)) -> 0.10140044 | DI8: =DF8*($F8)*(1/$D8)*(1/$DE8)*(1/$I8)*(12) -> 19.472265 | DJ8: 44491.59 | DK8: 44498.623 | DL8: =(DK8-DJ8) -> 7.0333333 | DM8: 276.97687 | DN8: 1416.54 | DO8: 0.65 | DP8: =DN8*($F8)*(1/$D8)*(1/$DM8)*(1/$I8)*(12)*(1/(DL8*24)) -> 0.073867047 | DQ8: =DN8*($F8)*(1/$D8)*(1/$DM8)*(1/$I8)*(12) -> 12.468758 | DR8: 44498.637 | DS8: 44505.57 | DT8: =(DS8-DR8) -> 6.9326389 | DU8: 276.60067 | DV8: 827.261 | DW8: 0.382 | DX8: =DV8*($F8)*(1/$D8)*(1/$DU8)*(1/$I8)*(12)*(1/(DT8*24)) -> 0.043824539 | DY8: =DV8*($F8)*(1/$D8)*(1/$DU8)*(1/$I8)*(12) -> 7.2916729 | DZ8: 44505.58 | EA8: 44512.564 | EB8: =(EA8-DZ8) -> 6.9840278 | EC8: 277.08092 | ED8: 719.008 | EE8: 0.522 | EF8: =ED8*($F8)*(1/$D8)*(1/$EC8)*(1/$I8)*(12)*(1/(EB8*24)) -> 0.037743985 | EG8: =ED8*($F8)*(1/$D8)*(1/$EC8)*(1/$I8)*(12) -> 6.326521 | EH8: 44512.626 | EI8: 44521.658 | EJ8: =(EI8-EH8) -> 9.0319444 | EK8: 276.87229 | EL8: 711.353 | EM8: 0.323 | EN8: =EL8*($F8)*(1/$D8)*(1/$EK8)*(1/$I8)*(12)*(1/(EJ8*24)) -> 0.028896884 | EO8: =EL8*($F8)*(1/$D8)*(1/$EK8)*(1/$I8)*(12) -> 6.2638813 | EP8: 44521.722 | EQ8: 44530.541 | ER8: =(EQ8-EP8) -> 8.81875 | ES8: 276.6425 | ET8: 778.594 | EU8: 0.596 | EV8: =ET8*($F8)*(1/$D8)*(1/$ES8)*(1/$I8)*(12)*(1/(ER8*24)) -> 0.032419904 | EW8: =ET8*($F8)*(1/$D8)*(1/$ES8)*(1/$I8)*(12) -> 6.8616727 | EX8: 44530.612 | EY8: 44539.578 | EZ8: =(EY8-EX8) -> 8.9666667 | FA8: 276.01467 | FB8: 705.917 | FC8: 0.327 | FD8: =FB8*($F8)*(1/$D8)*(1/$FA8)*(1/$I8)*(12)*(1/(EZ8*24)) -> 0.028974574 | FE8: =FB8*($F8)*(1/$D8)*(1/$FA8)*(1/$I8)*(12) -> 6.2353284 | FF8: 44539.627 | FG8: 44543.517 | FH8: =(FG8-FF8) -> 3.8902778 | FI8: 276.789 | FJ8: 362.895 | FK8: 0.253 | FL8: =FJ8*($F8)*(1/$D8)*(1/$FI8)*(1/$I8)*(12)*(1/(FH8*24)) -> 0.034235616 | FM8: =FJ8*($F8)*(1/$D8)*(1/$FI8)*(1/$I8)*(12) -> 3.1964654
A9: AT 4 REP 7 H2 | B9: 473.176 | C9: =Vol_soil_calc!L8 -> 14.451071 | D9: 0.082057366 | E9: 275.15 | F9: =(B9-C9)/1000 -> 0.45872493 | G9: 0.205 | H9: 29.508 | I9: =H9/(G9+1) -> 24.487967 | J9: 44447.816 | K9: 44447.86 | L9: =(K9-J9) -> 0.04375 | M9: 275.15 | N9: 181.748 | O9: 0.048 | P9: =N9*($F9)*(1/$D9)*(1/$M9)*(1/$I9)*(12)*(1/(L9*24)) -> 1.7233525 | Q9: =N9*($F9)*(1/$D9)*(1/$M9)*(1/$I9)*(12) -> 1.8095201 | S9: 0.66180556 | T9: =(S9-R9) -> 0.66180556 | U9: 275.15 | V9: 631.311 | W9: 0.662 | X9: =V9*($F9)*(1/$D9)*(1/$U9)*(1/$I9)*(12)*(1/(T9*24)) -> 0.39572681 | Y9: =V9*($F9)*(1/$D9)*(1/$U9)*(1/$I9)*(12) -> 6.2854609 | Z9: 44448.699 | AA9: 44449.574 | AB9: =(AA9-Z9) -> 0.87569444 | AC9: 278.97625 | AD9: 394.696 | AE9: 0.286 | AF9: =AD9*($F9)*(1/$D9)*(1/$AC9)*(1/$I9)*(12)*(1/(AB9*24)) -> 0.18441445 | AG9: =AD9*($F9)*(1/$D9)*(1/$AC9)*(1/$I9)*(12) -> 3.875777 | AH9: 44449.625 | AI9: 44451.698 | AJ9: =(AI10-AH10) -> 2.0694444 | AK9: 275.30392 | AL9: 286.888 | AM9: 0.199 | AN9: =AL9*($F9)*(1/$D9)*(1/$AK9)*(1/$I9)*(12)*(1/(AJ9*24)) -> 0.057477552 | AO9: =AL9*($F9)*(1/$D9)*(1/$AK9)*(1/$I9)*(12) -> 2.8547184 | AP9: 44451.778 | AQ9: 44453.624 | AR9: =(AQ9-AP9) -> 1.8458333 | AS9: 275.34575 | AT9: 151.131 | AU9: 0.16 | AV9: =AT9*($F9)*(1/$D9)*(1/$AS9)*(1/$I9)*(12)*(1/(AR9*24)) -> 0.03394179 | AW9: =AT9*($F9)*(1/$D9)*(1/$AS9)*(1/$I9)*(12) -> 1.5036213 | AX9: 44453.792 | AY9: 44456.575 | AZ9: =(AY9-AX9) -> 2.7826389 | BA9: 275.28258 | BB9: 167.422 | BC9: 0.037 | BD9: =BB9*($F9)*(1/$D9)*(1/$BA9)*(1/$I9)*(12)*(1/(AZ9*24)) -> 0.024947612 | BE9: =BB9*($F9)*(1/$D9)*(1/$BA9)*(1/$I9)*(12) -> 1.6660847 | BF9: 44456.599 | BG9: 44459.636 | BH9: =(BG9-BF9) -> 3.0368056 | BI9: 274.02612 | BJ9: 109.246 | BK9: 0.044 | BL9: =BJ9*($F9)*(1/$D9)*(1/$BI9)*(1/$I9)*(12)*(1/(BH9*24)) -> 0.01498472 | BM9: =BJ9*($F9)*(1/$D9)*(1/$BI9)*(1/$I9)*(12) -> 1.0921364 | BN9: 44459.66 | BO9: 44461.505 | BP9: =(BO9-BN9) -> 1.8451389 | BQ9: 276.14042 | BR9: 115.196 | BS9: 0.023 | BT9: =BR9*($F9)*(1/$D9)*(1/$BQ9)*(1/$I9)*(12)*(1/(BP9*24)) -> 0.025806577 | BU9: =BR9*($F9)*(1/$D9)*(1/$BQ9)*(1/$I9)*(12) -> 1.1428013 | BV9: 44461.515 | BW9: 44466.491 | BX9: =(BW9-BV9) -> 4.9763889 | BY9: 276.28675 | BZ9: 326.367 | CA9: 0.065 | CB9: =BZ9*($F9)*(1/$D9)*(1/$BY9)*(1/$I9)*(12)*(1/(BX9*24)) -> 0.027094673 | CC9: =BZ9*($F9)*(1/$D9)*(1/$BY9)*(1/$I9)*(12) -> 3.2360071 | CD9: 44466.567 | CE9: 44473.522 | CF9: =(CE9-CD9) -> 6.9555556 | CG9: 276.30758 | CH9: 924.799 | CI9: 0.034 | CJ9: =CH9*($F9)*(1/$D9)*(1/$CG9)*(1/$I9)*(12)*(1/(CF9*24)) -> 0.054925595 | CK9: =CH9*($F9)*(1/$D9)*(1/$CG9)*(1/$I9)*(12) -> 9.1689126 | CL9: 44473.559 | CM9: 44477.594 | CN9: =(CM9-CL9) -> 4.0354167 | CO9: 276.45387 | CP9: 1011.088 | CQ9: 0.021 | CR9: =CP9*($F9)*(1/$D9)*(1/$CO9)*(1/$I9)*(12)*(1/(CN9*24)) -> 0.10344987 | CS9: =CP9*($F9)*(1/$D9)*(1/$CO9)*(1/$I9)*(12) -> 10.01912 | CT9: 44477.635 | CU9: 44483.512 | CV9: =(CU9-CT9) -> 5.8777778 | CW9: 277.06033 | CX9: 1745.98 | CY9: 0.027 | CZ9: =CX9*($F9)*(1/$D9)*(1/$CW9)*(1/$I9)*(12)*(1/(CV9*24)) -> 0.12237813 | DA9: =CX9*($F9)*(1/$D9)*(1/$CW9)*(1/$I9)*(12) -> 17.263474 | DB9: 44483.569 | DC9: 44491.568 | DD9: =(DC9-DB9) -> 7.9986111 | DE9: 277.2485 | DF9: 1640.022 | DG9: 0.024 | DH9: =DF9*($F9)*(1/$D9)*(1/$DE9)*(1/$I9)*(12)*(1/(DD9*24)) -> 0.084414671 | DI9: =DF9*($F9)*(1/$D9)*(1/$DE9)*(1/$I9)*(12) -> 16.204803 | DJ9: 44491.59 | DK9: 44498.618 | DL9: =(DK9-DJ9) -> 7.0284722 | DM9: 276.97687 | DN9: 894.195 | DO9: 0.028 | DP9: =DN9*($F9)*(1/$D9)*(1/$DM9)*(1/$I9)*(12)*(1/(DL9*24)) -> 0.052429998 | DQ9: =DN9*($F9)*(1/$D9)*(1/$DM9)*(1/$I9)*(12) -> 8.8440668 | DR9: 44498.637 | DS9: 44505.56 | DT9: =(DS9-DR9) -> 6.9229167 | DU9: 276.60067 | DV9: 592.346 | DW9: 0.028 | DX9: =DV9*($F9)*(1/$D9)*(1/$DU9)*(1/$I9)*(12)*(1/(DT9*24)) -> 0.035308981 | DY9: =DV9*($F9)*(1/$D9)*(1/$DU9)*(1/$I9)*(12) -> 5.8665871 | DZ9: 44505.58 | EA9: 44512.615 | EB9: =(EA9-DZ9) -> 7.0354167 | EC9: 277.08092 | ED9: 401.257 | EE9: 0.026 | EF9: =ED9*($F9)*(1/$D9)*(1/$EC9)*(1/$I9)*(12)*(1/(EB9*24)) -> 0.02349515 | EG9: =ED9*($F9)*(1/$D9)*(1/$EC9)*(1/$I9)*(12) -> 3.9671561 | EH9: 44512.626 | EI9: 44521.668 | EJ9: =(EI9-EH9) -> 9.0423611 | EK9: 276.87229 | EL9: 449.807 | EM9: 0.039 | EN9: =EL9*($F9)*(1/$D9)*(1/$EK9)*(1/$I9)*(12)*(1/(EJ9*24)) -> 0.020507698 | EO9: =EL9*($F9)*(1/$D9)*(1/$EK9)*(1/$I9)*(12) -> 4.4505123 | EP9: 44521.722 | EQ9: 44530.56 | ER9: =(EQ9-EP9) -> 8.8375 | ES9: 276.6425 | ET9: 452.054 | EU9: 0.033 | EV9: =ET9*($F9)*(1/$D9)*(1/$ES9)*(1/$I9)*(12)*(1/(ER9*24)) -> 0.021105422 | EW9: =ET9*($F9)*(1/$D9)*(1/$ES9)*(1/$I9)*(12) -> 4.4764599 | EX9: 44530.612 | EY9: 44539.592 | EZ9: =(EY9-EX9) -> 8.9798611 | FA9: 276.01467 | FB9: 484.834 | FC9: 0.059 | FD9: =FB9*($F9)*(1/$D9)*(1/$FA9)*(1/$I9)*(12)*(1/(EZ9*24)) -> 0.022327666 | FE9: =FB9*($F9)*(1/$D9)*(1/$FA9)*(1/$I9)*(12) -> 4.8119842 | FF9: 44539.627 | FG9: 44543.505 | FH9: =(FG9-FF9) -> 3.8777778 | FI9: 276.789 | FJ9: 217.237 | FK9: 0.023 | FL9: =FJ9*($F9)*(1/$D9)*(1/$FI9)*(1/$I9)*(12)*(1/(FH9*24)) -> 0.02310224 | FM9: =FJ9*($F9)*(1/$D9)*(1/$FI9)*(1/$I9)*(12) -> 2.1500485
A10: AT 4 REP 8 H2 | B10: 473.176 | C10: =Vol_soil_calc!L9 -> 17.197235 | D10: 0.082057366 | E10: 275.15 | F10: =(B10-C10)/1000 -> 0.45597877 | G10: 0.28 | H10: 33.095 | I10: =H10/(G10+1) -> 25.855469 | J10: 44447.816 | K10: 44447.866 | L10: =(K10-J10) -> 0.05 | M10: 275.15 | N10: 248.449 | O10: 0.125 | P10: =N10*($F10)*(1/$D10)*(1/$M10)*(1/$I10)*(12)*(1/(L10*24)) -> 1.9406283 | Q10: =N10*($F10)*(1/$D10)*(1/$M10)*(1/$I10)*(12) -> 2.328754 | S10: 0.66597222 | T10: =(S10-R10) -> 0.66597222 | U10: 275.15 | V10: 956.298 | W10: 0.629 | X10: =V10*($F10)*(1/$D10)*(1/$U10)*(1/$I10)*(12)*(1/(T10*24)) -> 0.56080548 | Y10: =V10*($F10)*(1/$D10)*(1/$U10)*(1/$I10)*(12) -> 8.9635409 | Z10: 44448.699 | AA10: 44449.578 | AB10: =(AA10-Z10) -> 0.87986111 | AC10: 278.97625 | AD10: 429.044 | AE10: 0.158 | AF10: =AD10*($F10)*(1/$D10)*(1/$AC10)*(1/$I10)*(12)*(1/(AB10*24)) -> 0.18783007 | AG10: =AD10*($F10)*(1/$D10)*(1/$AC10)*(1/$I10)*(12) -> 3.9663449 | AH10: 44449.625 | AI10: 44451.694 | AJ10: =(AI10-AH10) -> 2.0694444 | AK10: 275.30392 | AL10: 239.731 | AM10: 0.024 | AN10: =AL10*($F10)*(1/$D10)*(1/$AK10)*(1/$I10)*(12)*(1/(AJ10*24)) -> 0.045217096 | AO10: =AL10*($F10)*(1/$D10)*(1/$AK10)*(1/$I10)*(12) -> 2.2457824 | AP10: 44451.785 | AQ10: 44453.629 | AR10: =(AQ10-AP10) -> 1.84375 | AS10: 275.34575 | AT10: 220.116 | AU10: 0.13 | AV10: =AT10*($F10)*(1/$D10)*(1/$AS10)*(1/$I10)*(12)*(1/(AR10*24)) -> 0.046592481 | AW10: =AT10*($F10)*(1/$D10)*(1/$AS10)*(1/$I10)*(12) -> 2.0617173 | AX10: 44453.792 | AY10: 44456.558 | AZ10: =(AY10-AX10) -> 2.7652778 | BA10: 275.28258 | BB10: 179.315 | BC10: 0.02 | BD10: =BB10*($F10)*(1/$D10)*(1/$BA10)*(1/$I10)*(12)*(1/(AZ10*24)) -> 0.025313008 | BE10: =BB10*($F10)*(1/$D10)*(1/$BA10)*(1/$I10)*(12) -> 1.67994 | BF10: 44456.599 | BG10: 44459.632 | BH10: =(BG10-BF10) -> 3.0326389 | BI10: 274.02612 | BJ10: 78.071 | BK10: 0.018 | BL10: =BJ10*($F10)*(1/$D10)*(1/$BI10)*(1/$I10)*(12)*(1/(BH10*24)) -> 0.010095358 | BM10: =BJ10*($F10)*(1/$D10)*(1/$BI10)*(1/$I10)*(12) -> 0.73477378 | BN10: 44459.66 | BO10: 44461.501 | BP10: =(BO10-BN10) -> 1.8409722 | BQ10: 276.14042 | BR10: 128.02 | BS10: 0.052 | BT10: =BR10*($F10)*(1/$D10)*(1/$BQ10)*(1/$I10)*(12)*(1/(BP10*24)) -> 0.027061087 | BU10: =BR10*($F10)*(1/$D10)*(1/$BQ10)*(1/$I10)*(12) -> 1.195649 | BV10: 44461.515 | BW10: 44466.487 | BX10: =(BW10-BV10) -> 4.9722222 | BY10: 276.28675 | BZ10: 204.137 | CA10: 0.033 | CB10: =BZ10*($F10)*(1/$D10)*(1/$BY10)*(1/$I10)*(12)*(1/(BX10*24)) -> 0.015968193 | CC10: =BZ10*($F10)*(1/$D10)*(1/$BY10)*(1/$I10)*(12) -> 1.9055377 | CD10: 44466.567 | CE10: 44473.528 | CF10: =(CE10-CD10) -> 6.9618056 | CG10: 276.30758 | CH10: 739.646 | CI10: 0.052 | CJ10: =CH10*($F10)*(1/$D10)*(1/$CG10)*(1/$I10)*(12)*(1/(CF10*24)) -> 0.041319385 | CK10: =CH10*($F10)*(1/$D10)*(1/$CG10)*(1/$I10)*(12) -> 6.9037807 | CL10: 44473.559 | CM10: 44477.599 | CN10: =(CM10-CL10) -> 4.0395833 | CO10: 276.45387 | CP10: 917.55 | CQ10: 0.029 | CR10: =CP10*($F10)*(1/$D10)*(1/$CO10)*(1/$I10)*(12)*(1/(CN10*24)) -> 0.088290733 | CS10: =CP10*($F10)*(1/$D10)*(1/$CO10)*(1/$I10)*(12) -> 8.5597865 | CT10: 44477.635 | CU10: 44483.517 | CV10: =(CU10-CT10) -> 5.8819444 | CW10: 277.06033 | CX10: 1863.965 | CY10: 0.046 | CZ10: =CX10*($F10)*(1/$D10)*(1/$CW10)*(1/$I10)*(12)*(1/(CV10*24)) -> 0.12290997 | DA10: =CX10*($F10)*(1/$D10)*(1/$CW10)*(1/$I10)*(12) -> 17.350791 | DB10: 44483.569 | DC10: 44491.544 | DD10: =(DC10-DB10) -> 7.975 | DE10: 277.2485 | DF10: 2152.499 | DG10: 0.033 | DH10: =DF10*($F10)*(1/$D10)*(1/$DE10)*(1/$I10)*(12)*(1/(DD10*24)) -> 0.10461349 | DI10: =DF10*($F10)*(1/$D10)*(1/$DE10)*(1/$I10)*(12) -> 20.023022 | DJ10: 44491.59 | DK10: 44498.614 | DL10: =(DK10-DJ10) -> 7.0243056 | DM10: 276.97687 | DN10: 1150.431 | DO10: 0.026 | DP10: =DN10*($F10)*(1/$D10)*(1/$DM10)*(1/$I10)*(12)*(1/(DL10*24)) -> 0.063541623 | DQ10: =DN10*($F10)*(1/$D10)*(1/$DM10)*(1/$I10)*(12) -> 10.712059 | DR10: 44498.637 | DS10: 44505.565 | DT10: =(DS10-DR10) -> 6.9277778 | DU10: 276.60067 | DV10: 769.016 | DW10: 0.03 | DX10: =DV10*($F10)*(1/$D10)*(1/$DU10)*(1/$I10)*(12)*(1/(DT10*24)) -> 0.04312537 | DY10: =DV10*($F10)*(1/$D10)*(1/$DU10)*(1/$I10)*(12) -> 7.1703116 | DZ10: 44505.58 | EA10: 44512.611 | EB10: =(EA10-DZ10) -> 7.03125 | EC10: 277.08092 | ED10: 553.089 | EE10: 0.027 | EF10: =ED10*($F10)*(1/$D10)*(1/$EC10)*(1/$I10)*(12)*(1/(EB10*24)) -> 0.03050707 | EG10: =ED10*($F10)*(1/$D10)*(1/$EC10)*(1/$I10)*(12) -> 5.1480681 | EH10: 44512.626 | EI10: 44521.627 | EJ10: =(EI10-EH10) -> 9.0013889 | EK10: 276.87229 | EL10: 536.811 | EM10: 0.039 | EN10: =EL10*($F10)*(1/$D10)*(1/$EK10)*(1/$I10)*(12)*(1/(EJ10*24)) -> 0.023146057 | EO10: =EL10*($F10)*(1/$D10)*(1/$EK10)*(1/$I10)*(12) -> 5.0003199 | EP10: 44521.722 | EQ10: 44530.528 | ER10: =(EQ10-EP10) -> 8.8055556 | ES10: 276.6425 | ET10: 483.926 | EU10: 0.038 | EV10: =ET10*($F10)*(1/$D10)*(1/$ES10)*(1/$I10)*(12)*(1/(ER10*24)) -> 0.021347545 | EW10: =ET10*($F10)*(1/$D10)*(1/$ES10)*(1/$I10)*(12) -> 4.5114477 | EX10: 44530.612 | EY10: 44539.57 | EZ10: =(EY10-EX10) -> 8.9583333 | FA10: 276.01467 | FB10: 441.315 | FC10: 0.031 | FD10: =FB10*($F10)*(1/$D10)*(1/$FA10)*(1/$I10)*(12)*(1/(EZ10*24)) -> 0.019179353 | FE10: =FB10*($F10)*(1/$D10)*(1/$FA10)*(1/$I10)*(12) -> 4.1235608 | FF10: 44539.627 | FG10: 44543.496 | FH10: =(FG10-FF10) -> 3.86875 | FI10: 276.789 | FJ10: 272.195 | FK10: 0.043 | FL10: =FJ10*($F10)*(1/$D10)*(1/$FI10)*(1/$I10)*(12)*(1/(FH10*24)) -> 0.027315257 | FM10: =FJ10*($F10)*(1/$D10)*(1/$FI10)*(1/$I10)*(12) -> 2.5362216
A11: FL1C4 REP 5 H2 | B11: 473.176 | C11: =Vol_soil_calc!L10 -> 27.612865 | D11: 0.082057366 | E11: 275.15 | F11: =(B11-C11)/1000 -> 0.44556313 | G11: 3.316 | H11: 30.701 | I11: =H11/(G11+1) -> 7.1132994 | J11: 44447.816 | K11: 44447.872 | L11: =(K11-J11) -> 0.055555556 | M11: 275.15 | N11: 128.599 | O11: 0.947 | P11: =N11*($F11)*(1/$D11)*(1/$M11)*(1/$I11)*(12)*(1/(L11*24)) -> 3.2109325 | Q11: =N11*($F11)*(1/$D11)*(1/$M11)*(1/$I11)*(12) -> 4.2812433 | S11: 0.67013889 | T11: =(S11-R11) -> 0.67013889 | U11: 275.15 | V11: 827.761 | W11: 5.429 | X11: =V11*($F11)*(1/$D11)*(1/$U11)*(1/$I11)*(12)*(1/(T11*24)) -> 1.7134097 | Y11: =V11*($F11)*(1/$D11)*(1/$U11)*(1/$I11)*(12) -> 27.557339 | Z11: 44448.699 | AA11: 44449.585 | AB11: =(AA11-Z11) -> 0.88611111 | AC11: 278.97625 | AD11: 946.641 | AE11: 3.733 | AF11: =AD11*($F11)*(1/$D11)*(1/$AC11)*(1/$I11)*(12)*(1/(AB11*24)) -> 1.4615729 | AG11: =AD11*($F11)*(1/$D11)*(1/$AC11)*(1/$I11)*(12) -> 31.082784 | AH11: 44449.625 | AI11: 44451.724 | AJ11: =(AI11-AH11) -> 2.0993056 | AK11: 275.30392 | AL11: 950.092 | AM11: 0.942 | AN11: =AL11*($F11)*(1/$D11)*(1/$AK11)*(1/$I11)*(12)*(1/(AJ11*24)) -> 0.62743424 | AO11: =AL11*($F11)*(1/$D11)*(1/$AK11)*(1/$I11)*(12) -> 31.612228 | AP11: 44451.785 | AQ11: 44453.637 | AR11: =(AQ11-AP11) -> 1.8520833 | AS11: 275.34575 | AT11: 885.26 | AU11: 0.01 | AV11: =AT11*($F11)*(1/$D11)*(1/$AS11)*(1/$I11)*(12)*(1/(AR11*24)) -> 0.66255592 | AW11: =AT11*($F11)*(1/$D11)*(1/$AS11)*(1/$I11)*(12) -> 29.450611 | AX11: 44453.792 | AY11: 44456.584 | AZ11: =(AY11-AX11) -> 2.7916667 | BA11: 275.28258 | BB11: 2610.592 | BC11: 0.802 | BD11: =BB11*($F11)*(1/$D11)*(1/$BA11)*(1/$I11)*(12)*(1/(AZ11*24)) -> 1.2965441 | BE11: =BB11*($F11)*(1/$D11)*(1/$BA11)*(1/$I11)*(12) -> 86.868457 | BF11: 44456.599 | BG11: 44459.599 | BH11: =(BG11-BF11) -> 3 | BI11: 274.02612 | BJ11: 1468.404 | BK11: 0.473 | BL11: =BJ11*($F11)*(1/$D11)*(1/$BI11)*(1/$I11)*(12)*(1/(BH11*24)) -> 0.68174652 | BM11: =BJ11*($F11)*(1/$D11)*(1/$BI11)*(1/$I11)*(12) -> 49.08575 | BN11: 44459.66 | BO11: 44461.461 | BP11: =(BO11-BN11) -> 1.8013889 | BQ11: 276.14042 | BR11: 1347.635 | BS11: 0.255 | BT11: =BR11*($F11)*(1/$D11)*(1/$BQ11)*(1/$I11)*(12)*(1/(BP11*24)) -> 1.0340116 | BU11: =BR11*($F11)*(1/$D11)*(1/$BQ11)*(1/$I11)*(12) -> 44.703769 | BV11: 44461.515 | BW11: 44466.519 | BX11: =(BW11-BV11) -> 5.0041667 | BY11: 276.28675 | BZ11: 9099.791 | CA11: 0.894 | CB11: =BZ11*($F11)*(1/$D11)*(1/$BY11)*(1/$I11)*(12)*(1/(BX11*24)) -> 2.5120611 | CC11: =BZ11*($F11)*(1/$D11)*(1/$BY11)*(1/$I11)*(12) -> 301.69853 | CD11: 44466.567 | CE11: 44473.534 | CF11: =(CE11-CD11) -> 6.9673611 | CG11: 276.30758 | CH11: 5505.804 | CI11: 0.417 | CJ11: =CH11*($F11)*(1/$D11)*(1/$CG11)*(1/$I11)*(12)*(1/(CF11*24)) -> 1.0915666 | CK11: =CH11*($F11)*(1/$D11)*(1/$CG11)*(1/$I11)*(12) -> 182.52812 | CL11: 44473.559 | CM11: 44477.613 | CN11: =(CM11-CL11) -> 4.0541667 | CO11: 276.45387 | CP11: 1807.189 | CQ11: 0.232 | CR11: =CP11*($F11)*(1/$D11)*(1/$CO11)*(1/$I11)*(12)*(1/(CN11*24)) -> 0.61541757 | CS11: =CP11*($F11)*(1/$D11)*(1/$CO11)*(1/$I11)*(12) -> 59.88013 | CT11: 44477.635 | CU11: 44483.553 | CV11: =(CU11-CT11) -> 5.9180556 | CW11: 277.06033 | CX11: 1668.509 | CY11: 0.071 | CZ11: =CX11*($F11)*(1/$D11)*(1/$CW11)*(1/$I11)*(12)*(1/(CV11*24)) -> 0.38838796 | DA11: =CX11*($F11)*(1/$D11)*(1/$CW11)*(1/$I11)*(12) -> 55.164037 | DB11: 44483.569 | DC11: 44491.58 | DD11: =(DC11-DB11) -> 8.0104167 | DE11: 277.2485 | DF11: 2148.078 | DG11: 0.084 | DH11: =DF11*($F11)*(1/$D11)*(1/$DE11)*(1/$I11)*(12)*(1/(DD11*24)) -> 0.36916144 | DI11: =DF11*($F11)*(1/$D11)*(1/$DE11)*(1/$I11)*(12) -> 70.971287 | DJ11: 44491.59 | DK11: 44498.582 | DL11: =(DK11-DJ11) -> 6.9923611 | DM11: 276.97687 | DN11: 1826.843 | DO11: 0.066 | DP11: =DN11*($F11)*(1/$D11)*(1/$DM11)*(1/$I11)*(12)*(1/(DL11*24)) -> 0.36001821 | DQ11: =DN11*($F11)*(1/$D11)*(1/$DM11)*(1/$I11)*(12) -> 60.417055 | DR11: 44498.637 | DS11: 44505.523 | DT11: =(DS11-DR11) -> 6.8854167 | DU11: 276.60067 | DV11: 2365.81 | DW11: 0.114 | DX11: =DV11*($F11)*(1/$D11)*(1/$DU11)*(1/$I11)*(12)*(1/(DT11*24)) -> 0.47411862 | DY11: =DV11*($F11)*(1/$D11)*(1/$DU11)*(1/$I11)*(12) -> 78.348102 | DZ11: 44505.58 | EA11: 44512.572 | EB11: =(EA11-DZ11) -> 6.9916667 | EC11: 277.08092 | ED11: 2409.877 | EE11: 0.063 | EF11: =ED11*($F11)*(1/$D11)*(1/$EC11)*(1/$I11)*(12)*(1/(EB11*24)) -> 0.47478626 | EG11: =ED11*($F11)*(1/$D11)*(1/$EC11)*(1/$I11)*(12) -> 79.669135 | EH11: 44512.626 | EI11: 44521.637 | EJ11: =(EI11-EH11) -> 9.0111111 | EK11: 276.87229 | EL11: 2521.062 | EM11: 0.091 | EN11: =EL11*($F11)*(1/$D11)*(1/$EK11)*(1/$I11)*(12)*(1/(EJ11*24)) -> 0.38567038 | EO11: =EL11*($F11)*(1/$D11)*(1/$EK11)*(1/$I11)*(12) -> 83.407647 | EP11: 44521.722 | EQ11: 44530.552 | ER11: =(EQ11-EP11) -> 8.8298611 | ES11: 276.6425 | ET11: 2119.414 | EU11: 0.093 | EV11: =ET11*($F11)*(1/$D11)*(1/$ES11)*(1/$I11)*(12)*(1/(ER11*24)) -> 0.33115676 | EW11: =ET11*($F11)*(1/$D11)*(1/$ES11)*(1/$I11)*(12) -> 70.177636 | EX11: 44530.612 | EY11: 44539.585 | EZ11: =(EY11-EX11) -> 8.9736111 | FA11: 276.01467 | FB11: 1897.231 | FC11: 0.062 | FD11: =FB11*($F11)*(1/$D11)*(1/$FA11)*(1/$I11)*(12)*(1/(EZ11*24)) -> 0.29235559 | FE11: =FB11*($F11)*(1/$D11)*(1/$FA11)*(1/$I11)*(12) -> 62.963649 | FF11: 44539.627 | FG11: 44543.522 | FH11: =(FG11-FF11) -> 3.8944444 | FI11: 276.789 | FJ11: 986.849 | FK11: 0.033 | FL11: =FJ11*($F11)*(1/$D11)*(1/$FI11)*(1/$I11)*(12)*(1/(FH11*24)) -> 0.34941936 | FM11: =FJ11*($F11)*(1/$D11)*(1/$FI11)*(1/$I11)*(12) -> 32.659063
A12: FL1C4 REP 6 H2 | B12: 473.176 | C12: =Vol_soil_calc!L11 -> 26.721798 | D12: 0.082057366 | E12: 275.15 | F12: =(B12-C12)/1000 -> 0.4464542 | G12: 3.634 | H12: 29.484 | I12: =H12/(G12+1) -> 6.3625378 | J12: 44447.816 | K12: 44447.877 | L12: =(K12-J12) -> 0.061111111 | M12: 275.15 | N12: 128.871 | O12: 0.862 | P12: =N12*($F12)*(1/$D12)*(1/$M12)*(1/$I12)*(12)*(1/(L12*24)) -> 3.2769097 | Q12: =N12*($F12)*(1/$D12)*(1/$M12)*(1/$I12)*(12) -> 4.8061342 | S12: 0.67430556 | T12: =(S12-R12) -> 0.67430556 | U12: 275.15 | V12: 753.706 | W12: 5.265 | X12: =V12*($F12)*(1/$D12)*(1/$U12)*(1/$I12)*(12)*(1/(T12*24)) -> 1.7368995 | Y12: =V12*($F12)*(1/$D12)*(1/$U12)*(1/$I12)*(12) -> 28.108824 | Z12: 44448.699 | AA12: 44449.592 | AB12: =(AA12-Z12) -> 0.89375 | AC12: 278.97625 | AD12: 815.593 | AE12: 2.08 | AF12: =AD12*($F12)*(1/$D12)*(1/$AC12)*(1/$I12)*(12)*(1/(AB12*24)) -> 1.398586 | AG12: =AD12*($F12)*(1/$D12)*(1/$AC12)*(1/$I12)*(12) -> 29.99967 | AH12: 44449.625 | AI12: 44451.719 | AJ12: =(AI12-AH12) -> 2.0944444 | AK12: 275.30392 | AL12: 851.629 | AM12: 0.213 | AN12: =AL12*($F12)*(1/$D12)*(1/$AK12)*(1/$I12)*(12)*(1/(AJ12*24)) -> 0.63149248 | AO12: =AL12*($F12)*(1/$D12)*(1/$AK12)*(1/$I12)*(12) -> 31.743022 | AP12: 44451.778 | AQ12: 44453.641 | AR12: =(AQ12-AP12) -> 1.8631944 | AS12: 275.34575 | AT12: 1009.492 | AU12: 0.01 | AV12: =AT12*($F12)*(1/$D12)*(1/$AS12)*(1/$I12)*(12)*(1/(AR12*24)) -> 0.84132791 | AW12: =AT12*($F12)*(1/$D12)*(1/$AS12)*(1/$I12)*(12) -> 37.62138 | AX12: 44453.792 | AY12: 44456.539 | AZ12: =(AY12-AX12) -> 2.7465278 | BA12: 275.28258 | BB12: 1186.856 | BC12: 0.052 | BD12: =BB12*($F12)*(1/$D12)*(1/$BA12)*(1/$I12)*(12)*(1/(AZ12*24)) -> 0.67117268 | BE12: =BB12*($F12)*(1/$D12)*(1/$BA12)*(1/$I12)*(12) -> 44.241466 | BF12: 44456.599 | BG12: 44459.603 | BH12: =(BG12-BF12) -> 3.0034722 | BI12: 274.02612 | BJ12: 338.317 | BK12: 0.113 | BL12: =BJ12*($F12)*(1/$D12)*(1/$BI12)*(1/$I12)*(12)*(1/(BH12*24)) -> 0.1757548 | BM12: =BJ12*($F12)*(1/$D12)*(1/$BI12)*(1/$I12)*(12) -> 12.668992 | BN12: 44459.66 | BO12: 44461.465 | BP12: =(BO12-BN12) -> 1.8055556 | BQ12: 276.14042 | BR12: 502.13 | BS12: 0.261 | BT12: =BR12*($F12)*(1/$D12)*(1/$BQ12)*(1/$I12)*(12)*(1/(BP12*24)) -> 0.43060028 | BU12: =BR12*($F12)*(1/$D12)*(1/$BQ12)*(1/$I12)*(12) -> 18.659346 | BV12: 44461.515 | BW12: 44466.514 | BX12: =(BW12-BV12) -> 4.9993056 | BY12: 276.28675 | BZ12: 950.776 | CA12: 0.06 | CB12: =BZ12*($F12)*(1/$D12)*(1/$BY12)*(1/$I12)*(12)*(1/(BX12*24)) -> 0.29431164 | CC12: =BZ12*($F12)*(1/$D12)*(1/$BY12)*(1/$I12)*(12) -> 35.312492 | CD12: 44466.567 | CE12: 44473.54 | CF12: =(CE12-CD12) -> 6.9736111 | CG12: 276.30758 | CH12: 1310.162 | CI12: 0.35 | CJ12: =CH12*($F12)*(1/$D12)*(1/$CG12)*(1/$I12)*(12)*(1/(CF12*24)) -> 0.29071902 | CK12: =CH12*($F12)*(1/$D12)*(1/$CG12)*(1/$I12)*(12) -> 48.656673 | CL12: 44473.559 | CM12: 44477.62 | CN12: =(CM12-CL12) -> 4.0611111 | CO12: 276.45387 | CP12: 833.855 | CQ12: 0.1 | CR12: =CP12*($F12)*(1/$D12)*(1/$CO12)*(1/$I12)*(12)*(1/(CN12*24)) -> 0.3175572 | CS12: =CP12*($F12)*(1/$D12)*(1/$CO12)*(1/$I12)*(12) -> 30.951241 | CT12: 44477.635 | CU12: 44483.557 | CV12: =(CU12-CT12) -> 5.9222222 | CW12: 277.06033 | CX12: 1075.784 | CY12: 0.12 | CZ12: =CX12*($F12)*(1/$D12)*(1/$CW12)*(1/$I12)*(12)*(1/(CV12*24)) -> 0.28032705 | DA12: =CX12*($F12)*(1/$D12)*(1/$CW12)*(1/$I12)*(12) -> 39.843818 | DB12: 44483.569 | DC12: 44491.529 | DD12: =(DC12-DB12) -> 7.9597222 | DE12: 277.2485 | DF12: 1411.797 | DG12: 0.139 | DH12: =DF12*($F12)*(1/$D12)*(1/$DE12)*(1/$I12)*(12)*(1/(DD12*24)) -> 0.27352946 | DI12: =DF12*($F12)*(1/$D12)*(1/$DE12)*(1/$I12)*(12) -> 52.253245 | DJ12: 44491.59 | DK12: 44498.585 | DL12: =(DK12-DJ12) -> 6.9958333 | DM12: 276.97687 | DN12: 1908.414 | DO12: 0.078 | DP12: =DN12*($F12)*(1/$D12)*(1/$DM12)*(1/$I12)*(12)*(1/(DL12*24)) -> 0.42110326 | DQ12: =DN12*($F12)*(1/$D12)*(1/$DM12)*(1/$I12)*(12) -> 70.703237 | DR12: 44498.637 | DS12: 44505.528 | DT12: =(DS12-DR12) -> 6.8909722 | DU12: 276.60067 | DV12: 2294.895 | DW12: 0.08 | DX12: =DV12*($F12)*(1/$D12)*(1/$DU12)*(1/$I12)*(12)*(1/(DT12*24)) -> 0.51478759 | DY12: =DV12*($F12)*(1/$D12)*(1/$DU12)*(1/$I12)*(12) -> 85.137288 | DZ12: 44505.58 | EA12: 44512.578 | EB12: =(EA12-DZ12) -> 6.9979167 | EC12: 277.08092 | ED12: 2125.698 | EE12: 0.098 | EF12: =ED12*($F12)*(1/$D12)*(1/$EC12)*(1/$I12)*(12)*(1/(EB12*24)) -> 0.4687326 | EG12: =ED12*($F12)*(1/$D12)*(1/$EC12)*(1/$I12)*(12) -> 78.723639 | EH12: 44512.626 | EI12: 44521.629 | EJ12: =(EI12-EH12) -> 9.0034722 | EK12: 276.87229 | EL12: 1847.332 | EM12: 1.502 | EN12: =EL12*($F12)*(1/$D12)*(1/$EK12)*(1/$I12)*(12)*(1/(EJ12*24)) -> 0.3168505 | EO12: =EL12*($F12)*(1/$D12)*(1/$EK12)*(1/$I12)*(12) -> 68.466113 | EP12: 44521.722 | EQ12: 44530.569 | ER12: =(EQ12-EP12) -> 8.8465278 | ES12: 276.6425 | ET12: 1788.001 | EU12: 0.119 | EV12: =ET12*($F12)*(1/$D12)*(1/$ES12)*(1/$I12)*(12)*(1/(ER12*24)) -> 0.31237408 | EW12: =ET12*($F12)*(1/$D12)*(1/$ES12)*(1/$I12)*(12) -> 66.322223 | EX12: 44530.612 | EY12: 44539.61 | EZ12: =(EY12-EX12) -> 8.9986111 | FA12: 276.01467 | FB12: 1669.79 | FC12: 0.073 | FD12: =FB12*($F12)*(1/$D12)*(1/$FA12)*(1/$I12)*(12)*(1/(EZ12*24)) -> 0.28744396 | FE12: =FB12*($F12)*(1/$D12)*(1/$FA12)*(1/$I12)*(12) -> 62.078314 | FF12: 44539.627 | FG12: 44543.528 | FH12: =(FG12-FF12) -> 3.9006944 | FI12: 276.789 | FJ12: 953.268 | FK12: 0.036 | FL12: =FJ12*($F12)*(1/$D12)*(1/$FI12)*(1/$I12)*(12)*(1/(FH12*24)) -> 0.37750545 | FM12: =FJ12*($F12)*(1/$D12)*(1/$FI12)*(1/$I12)*(12) -> 35.340802
